Workbook

Sheet 요약
A1: 외화 IG 크레딧 포트 운용 요약
A2: ="기준일 "&TEXT(설정!$C$4,"yyyy-mm-dd")&" | 펀드: "&IF(설정!$C$5="선택펀드","선택("&TRIM(IF(설정!$G$16="Y",설정!$F$16&" ","")&IF(설정!$G$17="Y",설정!$F$17&" ","")&IF(설정!$G$18="Y",설정!$F$18&" ","")&IF(설정!$G$19="Y",설정!$F$19&" ","")&IF(설정!$G$20="Y",설정!$F$20&" ","")&IF(설정!$G$21="Y",설정!$F$21&" ","")&IF(설정!$G$22="Y",설정!$F$22&" ","")&IF(설정!$G$23="Y",설정!$F$23&" ","")&IF(설정!$G$24="Y",설정!$F$24&" ","")&IF(설정!$G$25="Y",설정!$F$25&" ","")&IF(설정!$G$26="Y",설정!$F$26&" ","")&IF(설정!$G$27="Y",설정!$F$27&" ","")&IF(설정!$G$28="Y",설정!$F$28&" ","")&IF(설정!$G$29="Y",설정!$F$29&" ","")&IF(설정!$G$30="Y",설정!$F$30&" ","")&IF(설정!$G$31="Y",설정!$F$31&" ","")&IF(설정!$G$32="Y",설정!$F$32&" ","")&IF(설정!$G$33="Y",설정!$F$33&" ","")&IF(설정!$G$34="Y",설정!$F$34&" ","")&IF(설정!$G$35="Y",설정!$F$35&" ","")&IF(설정!$G$36="Y",설정!$F$36&" ",""))&")",설정!$C$5&"")&" | 평가금액(USD 환산) 기준" -> 기준일 2026-10-01 | 펀드: 선택(28096 34507 34578 38168) | 평가금액(USD 환산) 기준
A3: =IF(COUNTIF(설정!$M$7:$M$37,"헤더없음")>0,"⚠ 원자료 헤더를 찾지 못한 항목이 있습니다 — [설정] 헤더 매핑 확인","")&IF(INDEX(원자료_잔고!$A$1:$EZ$1500,설정!$L$5+800+1,설정!$L$8)&""<>""," ⚠ 잔고 행 수가 800개를 초과 — 일부 미집계","")
A4: 지표 | B4: 값 | D4: 1년 보유 시나리오 (선형 근사, 볼록성·듀레이션 감소 무시 / 총수익은 차등·비례 쇼크 기준)
A5: 평가금액($M) | B5: =SUMIFS(보유분석!$AA$2:$AA$801,보유분석!$AC$2:$AC$801,1) -> 1409.3986 | D5: 시나리오 | E5: 금리Δ(bp) | F5: 기본 스프레드Δ(bp) | G5: 캐리+롤다운($) | H5: 금리손익($) | I5: 스프레드손익 균등($) | J5: 스프레드손익 차등·비례($) | K5: 총수익($) | L5: 총수익률(%)
A6: 액면($M) | B6: =SUMIFS(보유분석!$X$2:$X$801,보유분석!$AC$2:$AC$801,1) -> 1441.935 | D6: 기본(무변동) | E6: 0 | F6: 0 | G6: =$B$15 -> 82103986 | H6: =-$B$11*E6 -> 0 | I6: =-$B$12*F6 -> 0 | J6: =-$B$19*F6 -> 0 | K6: =G6+H6+J6 -> 82103986 | L6: =K6/($B$5*1000000) -> 0.058254622
A7: 종목수 / 로트수 | B7: =SUMPRODUCT((보유분석!$AC$2:$AC$801=1)/(COUNTIFS(보유분석!$B$2:$B$801,보유분석!$B$2:$B$801,보유분석!$AC$2:$AC$801,1)+(보유분석!$AC$2:$AC$801<>1)))&" / "&COUNTIFS(보유분석!$AC$2:$AC$801,1) -> 134 / 278 | D7: 금리 상승 | E7: =설정!$C$9 -> 50 | F7: 0 | G7: =$B$15 -> 82103986 | H7: =-$B$11*E7 -> -18961159 | I7: =-$B$12*F7 -> 0 | J7: =-$B$19*F7 -> 0 | K7: =G7+H7+J7 -> 63142827 | L7: =K7/($B$5*1000000) -> 0.044801254
A8: 가중 YTM(%) | B8: =SUMIFS(보유분석!$BA$2:$BA$801,보유분석!$AC$2:$AC$801,1)/SUMIFS(보유분석!$BB$2:$BB$801,보유분석!$AC$2:$AC$801,1) -> 5.6600358 | D8: 금리 하락 | E8: =-설정!$C$9 -> -50 | F8: 0 | G8: =$B$15 -> 82103986 | H8: =-$B$11*E8 -> 18961159 | I8: =-$B$12*F8 -> 0 | J8: =-$B$19*F8 -> 0 | K8: =G8+H8+J8 -> 1.0106514e+08 | L8: =K8/($B$5*1000000) -> 0.07170799
A9: 가중 G-spread(bp, 크레딧) | B9: =SUMIFS(보유분석!$BC$2:$BC$801,보유분석!$AC$2:$AC$801,1)/SUMIFS(보유분석!$BD$2:$BD$801,보유분석!$AC$2:$AC$801,1) -> 66.114006 | D9: 스프레드 확대 | E9: 0 | F9: =설정!$C$10 -> 25 | G9: =$B$15 -> 82103986 | H9: =-$B$11*E9 -> 0 | I9: =-$B$12*F9 -> -9219866.1 | J9: =-$B$19*F9 -> -10177025 | K9: =G9+H9+J9 -> 71926960 | L9: =K9/($B$5*1000000) -> 0.051033794
A10: 가중 듀레이션(년) | B10: =SUMIFS(보유분석!$BE$2:$BE$801,보유분석!$AC$2:$AC$801,1)/SUMIFS(보유분석!$BF$2:$BF$801,보유분석!$AC$2:$AC$801,1) -> 2.6906736 | D10: 스프레드 축소 | E10: 0 | F10: =-설정!$C$10 -> -25 | G10: =$B$15 -> 82103986 | H10: =-$B$11*E10 -> 0 | I10: =-$B$12*F10 -> 9219866.1 | J10: =-$B$19*F10 -> 10177025 | K10: =G10+H10+J10 -> 92281011 | L10: =K10/($B$5*1000000) -> 0.06547545
A11: DV01($/bp) | B11: =SUMIFS(보유분석!$AM$2:$AM$801,보유분석!$AC$2:$AC$801,1) -> 379223.18 | D11: 리스크오프(금리↓·스프레드↑) | E11: =-설정!$C$9 -> -50 | F11: =설정!$C$10 -> 25 | G11: =$B$15 -> 82103986 | H11: =-$B$11*E11 -> 18961159 | I11: =-$B$12*F11 -> -9219866.1 | J11: =-$B$19*F11 -> -10177025 | K11: =G11+H11+J11 -> 90888119 | L11: =K11/($B$5*1000000) -> 0.064487162
A12: CR01($/bp, 국채 제외) | B12: =SUMIFS(보유분석!$AN$2:$AN$801,보유분석!$AC$2:$AC$801,1) -> 368794.64 | D12: 스태그(금리↑·스프레드↑) | E12: =설정!$C$9 -> 50 | F12: =설정!$C$10 -> 25 | G12: =$B$15 -> 82103986 | H12: =-$B$11*E12 -> -18961159 | I12: =-$B$12*F12 -> -9219866.1 | J12: =-$B$19*F12 -> -10177025 | K12: =G12+H12+J12 -> 52965802 | L12: =K12/($B$5*1000000) -> 0.037580426
A13: 1Y 캐리($) | B13: =SUMIFS(보유분석!$AO$2:$AO$801,보유분석!$AC$2:$AC$801,1) -> 79772468
A14: 1Y 스프레드 롤다운($) | B14: =SUMIFS(보유분석!$AU$2:$AU$801,보유분석!$AC$2:$AC$801,1) -> 2331517.4 | D14: 손익분기 기본 스프레드 확대폭(bp) — 균등 (캐리+롤다운 ÷ CR01) | L14: =IF(B12=0,"",B15/B12) -> 222.62792
A15: 1Y 기대수익($) = 캐리+롤다운 | B15: =B13+B14 -> 82103986 | D15: 손익분기 기본 스프레드 확대폭(bp) — 차등·비례 (캐리+롤다운 ÷ 조정 CR01) | L15: =IF(B19=0,"",B15/B19) -> 201.68955
A16: 1Y 기대수익률(%, 평가금액 대비) | B16: =B15/(B5*1000000) -> 0.058254622 | D16: 크레딧 손익분기(bp) — (G-spread+롤다운) ÷ 크레딧 듀레이션 | L16: =버킷분석!J16 -> 31.468574
A17: 평가손익($) | B17: =SUMIFS(보유분석!$AP$2:$AP$801,보유분석!$AC$2:$AC$801,1) -> -44901234
A18: 국채 비중 | B18: =SUMIFS(보유분석!$AA$2:$AA$801,보유분석!$AC$2:$AC$801,1,보유분석!$Y$2:$Y$801,1)/B5 -> 0.01199431 | D18: 운용코드별 (잔고 로트 기준 — 펀드별 정확히 분리)
A19: 쇼크조정 CR01($/bp) | B19: =SUMIFS(보유분석!$AZ$2:$AZ$801,보유분석!$AC$2:$AC$801,1) -> 407081.01 | D19: 운용코드 | E19: 평가금액($M) | F19: 가중YTM(%) | G19: 가중G(bp) | H19: 가중듀레이션 | I19: DV01($/bp) | J19: 1Y기대수익률(%) | K19: 종목수
A20: G-spread 커버리지(크레딧 평가금액) | B20: =SUMIFS(보유분석!$BD$2:$BD$801,보유분석!$AC$2:$AC$801,1)/SUMIFS(보유분석!$BI$2:$BI$801,보유분석!$AC$2:$AC$801,1) -> 0.97796717 | D20: 28096 | E20: =SUMPRODUCT((보유분석!$C$2:$C$801=$D20&"")*(보유분석!$Q$2:$Q$801=1)*($D20<>"")*보유분석!$AA$2:$AA$801) -> 498.56029 | F20: =IF(SUMPRODUCT((보유분석!$C$2:$C$801=$D20&"")*(보유분석!$Q$2:$Q$801=1)*($D20<>"")*보유분석!$BB$2:$BB$801)=0,"",SUMPRODUCT((보유분석!$C$2:$C$801=$D20&"")*(보유분석!$Q$2:$Q$801=1)*($D20<>"")*보유분석!$BA$2:$BA$801)/SUMPRODUCT((보유분석!$C$2:$C$801=$D20&"")*(보유분석!$Q$2:$Q$801=1)*($D20<>"")*보유분석!$BB$2:$BB$801)) -> 5.6677356 | G20: =IF(SUMPRODUCT((보유분석!$C$2:$C$801=$D20&"")*(보유분석!$Q$2:$Q$801=1)*($D20<>"")*보유분석!$BD$2:$BD$801)=0,"",SUMPRODUCT((보유분석!$C$2:$C$801=$D20&"")*(보유분석!$Q$2:$Q$801=1)*($D20<>"")*보유분석!$BC$2:$BC$801)/SUMPRODUCT((보유분석!$C$2:$C$801=$D20&"")*(보유분석!$Q$2:$Q$801=1)*($D20<>"")*보유분석!$BD$2:$BD$801)) -> 72.179724 | H20: =IF(SUMPRODUCT((보유분석!$C$2:$C$801=$D20&"")*(보유분석!$Q$2:$Q$801=1)*($D20<>"")*보유분석!$BF$2:$BF$801)=0,"",SUMPRODUCT((보유분석!$C$2:$C$801=$D20&"")*(보유분석!$Q$2:$Q$801=1)*($D20<>"")*보유분석!$BE$2:$BE$801)/SUMPRODUCT((보유분석!$C$2:$C$801=$D20&"")*(보유분석!$Q$2:$Q$801=1)*($D20<>"")*보유분석!$BF$2:$BF$801)) -> 2.6548408 | I20: =SUMPRODUCT((보유분석!$C$2:$C$801=$D20&"")*(보유분석!$Q$2:$Q$801=1)*($D20<>"")*보유분석!$AM$2:$AM$801) -> 132359.82 | J20: =IF(E20=0,"",SUMPRODUCT((보유분석!$C$2:$C$801=$D20&"")*(보유분석!$Q$2:$Q$801=1)*($D20<>"")*보유분석!$AV$2:$AV$801)/(E20*1000000)) -> 0.058033334 | K20: =SUMPRODUCT((보유분석!$C$2:$C$801=$D20&"")*(보유분석!$Q$2:$Q$801=1)*($D20<>"")/(COUNTIFS(보유분석!$C$2:$C$801,보유분석!$C$2:$C$801,보유분석!$B$2:$B$801,보유분석!$B$2:$B$801,보유분석!$Q$2:$Q$801,1)+(보유분석!$Q$2:$Q$801<>1))) -> 54
A21: Cheap 보유 / Rich 보유 로트수 | B21: =COUNTIFS(보유분석!$AC$2:$AC$801,1,보유분석!$AR$2:$AR$801,"Cheap")&" / "&COUNTIFS(보유분석!$AC$2:$AC$801,1,보유분석!$AR$2:$AR$801,"Rich") -> 36 / 10 | D21: 34507 | E21: =SUMPRODUCT((보유분석!$C$2:$C$801=$D21&"")*(보유분석!$Q$2:$Q$801=1)*($D21<>"")*보유분석!$AA$2:$AA$801) -> 322.8779 | F21: =IF(SUMPRODUCT((보유분석!$C$2:$C$801=$D21&"")*(보유분석!$Q$2:$Q$801=1)*($D21<>"")*보유분석!$BB$2:$BB$801)=0,"",SUMPRODUCT((보유분석!$C$2:$C$801=$D21&"")*(보유분석!$Q$2:$Q$801=1)*($D21<>"")*보유분석!$BA$2:$BA$801)/SUMPRODUCT((보유분석!$C$2:$C$801=$D21&"")*(보유분석!$Q$2:$Q$801=1)*($D21<>"")*보유분석!$BB$2:$BB$801)) -> 5.6291576 | G21: =IF(SUMPRODUCT((보유분석!$C$2:$C$801=$D21&"")*(보유분석!$Q$2:$Q$801=1)*($D21<>"")*보유분석!$BD$2:$BD$801)=0,"",SUMPRODUCT((보유분석!$C$2:$C$801=$D21&"")*(보유분석!$Q$2:$Q$801=1)*($D21<>"")*보유분석!$BC$2:$BC$801)/SUMPRODUCT((보유분석!$C$2:$C$801=$D21&"")*(보유분석!$Q$2:$Q$801=1)*($D21<>"")*보유분석!$BD$2:$BD$801)) -> 54.933816 | H21: =IF(SUMPRODUCT((보유분석!$C$2:$C$801=$D21&"")*(보유분석!$Q$2:$Q$801=1)*($D21<>"")*보유분석!$BF$2:$BF$801)=0,"",SUMPRODUCT((보유분석!$C$2:$C$801=$D21&"")*(보유분석!$Q$2:$Q$801=1)*($D21<>"")*보유분석!$BE$2:$BE$801)/SUMPRODUCT((보유분석!$C$2:$C$801=$D21&"")*(보유분석!$Q$2:$Q$801=1)*($D21<>"")*보유분석!$BF$2:$BF$801)) -> 2.8216054 | I21: =SUMPRODUCT((보유분석!$C$2:$C$801=$D21&"")*(보유분석!$Q$2:$Q$801=1)*($D21<>"")*보유분석!$AM$2:$AM$801) -> 91103.403 | J21: =IF(E21=0,"",SUMPRODUCT((보유분석!$C$2:$C$801=$D21&"")*(보유분석!$Q$2:$Q$801=1)*($D21<>"")*보유분석!$AV$2:$AV$801)/(E21*1000000)) -> 0.057510806 | K21: =SUMPRODUCT((보유분석!$C$2:$C$801=$D21&"")*(보유분석!$Q$2:$Q$801=1)*($D21<>"")/(COUNTIFS(보유분석!$C$2:$C$801,보유분석!$C$2:$C$801,보유분석!$B$2:$B$801,보유분석!$B$2:$B$801,보유분석!$Q$2:$Q$801,1)+(보유분석!$Q$2:$Q$801<>1))) -> 49
D22: 10227 | E22: =SUMPRODUCT((보유분석!$C$2:$C$801=$D22&"")*(보유분석!$Q$2:$Q$801=1)*($D22<>"")*보유분석!$AA$2:$AA$801) -> 1.984683 | F22: =IF(SUMPRODUCT((보유분석!$C$2:$C$801=$D22&"")*(보유분석!$Q$2:$Q$801=1)*($D22<>"")*보유분석!$BB$2:$BB$801)=0,"",SUMPRODUCT((보유분석!$C$2:$C$801=$D22&"")*(보유분석!$Q$2:$Q$801=1)*($D22<>"")*보유분석!$BA$2:$BA$801)/SUMPRODUCT((보유분석!$C$2:$C$801=$D22&"")*(보유분석!$Q$2:$Q$801=1)*($D22<>"")*보유분석!$BB$2:$BB$801)) -> 4.9766452 | G22: =IF(SUMPRODUCT((보유분석!$C$2:$C$801=$D22&"")*(보유분석!$Q$2:$Q$801=1)*($D22<>"")*보유분석!$BD$2:$BD$801)=0,"",SUMPRODUCT((보유분석!$C$2:$C$801=$D22&"")*(보유분석!$Q$2:$Q$801=1)*($D22<>"")*보유분석!$BC$2:$BC$801)/SUMPRODUCT((보유분석!$C$2:$C$801=$D22&"")*(보유분석!$Q$2:$Q$801=1)*($D22<>"")*보유분석!$BD$2:$BD$801)) -> -1.9223279 | H22: =IF(SUMPRODUCT((보유분석!$C$2:$C$801=$D22&"")*(보유분석!$Q$2:$Q$801=1)*($D22<>"")*보유분석!$BF$2:$BF$801)=0,"",SUMPRODUCT((보유분석!$C$2:$C$801=$D22&"")*(보유분석!$Q$2:$Q$801=1)*($D22<>"")*보유분석!$BE$2:$BE$801)/SUMPRODUCT((보유분석!$C$2:$C$801=$D22&"")*(보유분석!$Q$2:$Q$801=1)*($D22<>"")*보유분석!$BF$2:$BF$801)) -> 0.95193727 | I22: =SUMPRODUCT((보유분석!$C$2:$C$801=$D22&"")*(보유분석!$Q$2:$Q$801=1)*($D22<>"")*보유분석!$AM$2:$AM$801) -> 188.92937 | J22: =IF(E22=0,"",SUMPRODUCT((보유분석!$C$2:$C$801=$D22&"")*(보유분석!$Q$2:$Q$801=1)*($D22<>"")*보유분석!$AV$2:$AV$801)/(E22*1000000)) -> 0.050151365 | K22: =SUMPRODUCT((보유분석!$C$2:$C$801=$D22&"")*(보유분석!$Q$2:$Q$801=1)*($D22<>"")/(COUNTIFS(보유분석!$C$2:$C$801,보유분석!$C$2:$C$801,보유분석!$B$2:$B$801,보유분석!$B$2:$B$801,보유분석!$Q$2:$Q$801,1)+(보유분석!$Q$2:$Q$801<>1))) -> 2
D23: 34578 | E23: =SUMPRODUCT((보유분석!$C$2:$C$801=$D23&"")*(보유분석!$Q$2:$Q$801=1)*($D23<>"")*보유분석!$AA$2:$AA$801) -> 583.03249 | F23: =IF(SUMPRODUCT((보유분석!$C$2:$C$801=$D23&"")*(보유분석!$Q$2:$Q$801=1)*($D23<>"")*보유분석!$BB$2:$BB$801)=0,"",SUMPRODUCT((보유분석!$C$2:$C$801=$D23&"")*(보유분석!$Q$2:$Q$801=1)*($D23<>"")*보유분석!$BA$2:$BA$801)/SUMPRODUCT((보유분석!$C$2:$C$801=$D23&"")*(보유분석!$Q$2:$Q$801=1)*($D23<>"")*보유분석!$BB$2:$BB$801)) -> 5.6703767 | G23: =IF(SUMPRODUCT((보유분석!$C$2:$C$801=$D23&"")*(보유분석!$Q$2:$Q$801=1)*($D23<>"")*보유분석!$BD$2:$BD$801)=0,"",SUMPRODUCT((보유분석!$C$2:$C$801=$D23&"")*(보유분석!$Q$2:$Q$801=1)*($D23<>"")*보유분석!$BC$2:$BC$801)/SUMPRODUCT((보유분석!$C$2:$C$801=$D23&"")*(보유분석!$Q$2:$Q$801=1)*($D23<>"")*보유분석!$BD$2:$BD$801)) -> 66.601558 | H23: =IF(SUMPRODUCT((보유분석!$C$2:$C$801=$D23&"")*(보유분석!$Q$2:$Q$801=1)*($D23<>"")*보유분석!$BF$2:$BF$801)=0,"",SUMPRODUCT((보유분석!$C$2:$C$801=$D23&"")*(보유분석!$Q$2:$Q$801=1)*($D23<>"")*보유분석!$BE$2:$BE$801)/SUMPRODUCT((보유분석!$C$2:$C$801=$D23&"")*(보유분석!$Q$2:$Q$801=1)*($D23<>"")*보유분석!$BF$2:$BF$801)) -> 2.6406637 | I23: =SUMPRODUCT((보유분석!$C$2:$C$801=$D23&"")*(보유분석!$Q$2:$Q$801=1)*($D23<>"")*보유분석!$AM$2:$AM$801) -> 153959.28 | J23: =IF(E23=0,"",SUMPRODUCT((보유분석!$C$2:$C$801=$D23&"")*(보유분석!$Q$2:$Q$801=1)*($D23<>"")*보유분석!$AV$2:$AV$801)/(E23*1000000)) -> 0.058854187 | K23: =SUMPRODUCT((보유분석!$C$2:$C$801=$D23&"")*(보유분석!$Q$2:$Q$801=1)*($D23<>"")/(COUNTIFS(보유분석!$C$2:$C$801,보유분석!$C$2:$C$801,보유분석!$B$2:$B$801,보유분석!$B$2:$B$801,보유분석!$Q$2:$Q$801,1)+(보유분석!$Q$2:$Q$801<>1))) -> 36
D24: 38038 | E24: =SUMPRODUCT((보유분석!$C$2:$C$801=$D24&"")*(보유분석!$Q$2:$Q$801=1)*($D24<>"")*보유분석!$AA$2:$AA$801) -> 290.42565 | F24: =IF(SUMPRODUCT((보유분석!$C$2:$C$801=$D24&"")*(보유분석!$Q$2:$Q$801=1)*($D24<>"")*보유분석!$BB$2:$BB$801)=0,"",SUMPRODUCT((보유분석!$C$2:$C$801=$D24&"")*(보유분석!$Q$2:$Q$801=1)*($D24<>"")*보유분석!$BA$2:$BA$801)/SUMPRODUCT((보유분석!$C$2:$C$801=$D24&"")*(보유분석!$Q$2:$Q$801=1)*($D24<>"")*보유분석!$BB$2:$BB$801)) -> 5.3548151 | G24: =IF(SUMPRODUCT((보유분석!$C$2:$C$801=$D24&"")*(보유분석!$Q$2:$Q$801=1)*($D24<>"")*보유분석!$BD$2:$BD$801)=0,"",SUMPRODUCT((보유분석!$C$2:$C$801=$D24&"")*(보유분석!$Q$2:$Q$801=1)*($D24<>"")*보유분석!$BC$2:$BC$801)/SUMPRODUCT((보유분석!$C$2:$C$801=$D24&"")*(보유분석!$Q$2:$Q$801=1)*($D24<>"")*보유분석!$BD$2:$BD$801)) -> 78.303108 | H24: =IF(SUMPRODUCT((보유분석!$C$2:$C$801=$D24&"")*(보유분석!$Q$2:$Q$801=1)*($D24<>"")*보유분석!$BF$2:$BF$801)=0,"",SUMPRODUCT((보유분석!$C$2:$C$801=$D24&"")*(보유분석!$Q$2:$Q$801=1)*($D24<>"")*보유분석!$BE$2:$BE$801)/SUMPRODUCT((보유분석!$C$2:$C$801=$D24&"")*(보유분석!$Q$2:$Q$801=1)*($D24<>"")*보유분석!$BF$2:$BF$801)) -> 5.4687482 | I24: =SUMPRODUCT((보유분석!$C$2:$C$801=$D24&"")*(보유분석!$Q$2:$Q$801=1)*($D24<>"")*보유분석!$AM$2:$AM$801) -> 158826.47 | J24: =IF(E24=0,"",SUMPRODUCT((보유분석!$C$2:$C$801=$D24&"")*(보유분석!$Q$2:$Q$801=1)*($D24<>"")*보유분석!$AV$2:$AV$801)/(E24*1000000)) -> 0.05411683 | K24: =SUMPRODUCT((보유분석!$C$2:$C$801=$D24&"")*(보유분석!$Q$2:$Q$801=1)*($D24<>"")/(COUNTIFS(보유분석!$C$2:$C$801,보유분석!$C$2:$C$801,보유분석!$B$2:$B$801,보유분석!$B$2:$B$801,보유분석!$Q$2:$Q$801,1)+(보유분석!$Q$2:$Q$801<>1))) -> 18
D25: 38064 | E25: =SUMPRODUCT((보유분석!$C$2:$C$801=$D25&"")*(보유분석!$Q$2:$Q$801=1)*($D25<>"")*보유분석!$AA$2:$AA$801) -> 8.011592 | F25: =IF(SUMPRODUCT((보유분석!$C$2:$C$801=$D25&"")*(보유분석!$Q$2:$Q$801=1)*($D25<>"")*보유분석!$BB$2:$BB$801)=0,"",SUMPRODUCT((보유분석!$C$2:$C$801=$D25&"")*(보유분석!$Q$2:$Q$801=1)*($D25<>"")*보유분석!$BA$2:$BA$801)/SUMPRODUCT((보유분석!$C$2:$C$801=$D25&"")*(보유분석!$Q$2:$Q$801=1)*($D25<>"")*보유분석!$BB$2:$BB$801)) -> 5.2818 | G25: =IF(SUMPRODUCT((보유분석!$C$2:$C$801=$D25&"")*(보유분석!$Q$2:$Q$801=1)*($D25<>"")*보유분석!$BD$2:$BD$801)=0,"",SUMPRODUCT((보유분석!$C$2:$C$801=$D25&"")*(보유분석!$Q$2:$Q$801=1)*($D25<>"")*보유분석!$BC$2:$BC$801)/SUMPRODUCT((보유분석!$C$2:$C$801=$D25&"")*(보유분석!$Q$2:$Q$801=1)*($D25<>"")*보유분석!$BD$2:$BD$801)) -> -6.955 | H25: =IF(SUMPRODUCT((보유분석!$C$2:$C$801=$D25&"")*(보유분석!$Q$2:$Q$801=1)*($D25<>"")*보유분석!$BF$2:$BF$801)=0,"",SUMPRODUCT((보유분석!$C$2:$C$801=$D25&"")*(보유분석!$Q$2:$Q$801=1)*($D25<>"")*보유분석!$BE$2:$BE$801)/SUMPRODUCT((보유분석!$C$2:$C$801=$D25&"")*(보유분석!$Q$2:$Q$801=1)*($D25<>"")*보유분석!$BF$2:$BF$801)) -> 0.0968 | I25: =SUMPRODUCT((보유분석!$C$2:$C$801=$D25&"")*(보유분석!$Q$2:$Q$801=1)*($D25<>"")*보유분석!$AM$2:$AM$801) -> 77.552211 | J25: =IF(E25=0,"",SUMPRODUCT((보유분석!$C$2:$C$801=$D25&"")*(보유분석!$Q$2:$Q$801=1)*($D25<>"")*보유분석!$AV$2:$AV$801)/(E25*1000000)) -> 0.052818 | K25: =SUMPRODUCT((보유분석!$C$2:$C$801=$D25&"")*(보유분석!$Q$2:$Q$801=1)*($D25<>"")/(COUNTIFS(보유분석!$C$2:$C$801,보유분석!$C$2:$C$801,보유분석!$B$2:$B$801,보유분석!$B$2:$B$801,보유분석!$Q$2:$Q$801,1)+(보유분석!$Q$2:$Q$801<>1))) -> 1
D26: 38070 | E26: =SUMPRODUCT((보유분석!$C$2:$C$801=$D26&"")*(보유분석!$Q$2:$Q$801=1)*($D26<>"")*보유분석!$AA$2:$AA$801) -> 10.563732 | F26: =IF(SUMPRODUCT((보유분석!$C$2:$C$801=$D26&"")*(보유분석!$Q$2:$Q$801=1)*($D26<>"")*보유분석!$BB$2:$BB$801)=0,"",SUMPRODUCT((보유분석!$C$2:$C$801=$D26&"")*(보유분석!$Q$2:$Q$801=1)*($D26<>"")*보유분석!$BA$2:$BA$801)/SUMPRODUCT((보유분석!$C$2:$C$801=$D26&"")*(보유분석!$Q$2:$Q$801=1)*($D26<>"")*보유분석!$BB$2:$BB$801)) -> 3.8967811 | G26: =IF(SUMPRODUCT((보유분석!$C$2:$C$801=$D26&"")*(보유분석!$Q$2:$Q$801=1)*($D26<>"")*보유분석!$BD$2:$BD$801)=0,"",SUMPRODUCT((보유분석!$C$2:$C$801=$D26&"")*(보유분석!$Q$2:$Q$801=1)*($D26<>"")*보유분석!$BC$2:$BC$801)/SUMPRODUCT((보유분석!$C$2:$C$801=$D26&"")*(보유분석!$Q$2:$Q$801=1)*($D26<>"")*보유분석!$BD$2:$BD$801)) -> 75.650222 | H26: =IF(SUMPRODUCT((보유분석!$C$2:$C$801=$D26&"")*(보유분석!$Q$2:$Q$801=1)*($D26<>"")*보유분석!$BF$2:$BF$801)=0,"",SUMPRODUCT((보유분석!$C$2:$C$801=$D26&"")*(보유분석!$Q$2:$Q$801=1)*($D26<>"")*보유분석!$BE$2:$BE$801)/SUMPRODUCT((보유분석!$C$2:$C$801=$D26&"")*(보유분석!$Q$2:$Q$801=1)*($D26<>"")*보유분석!$BF$2:$BF$801)) -> 2.4876688 | I26: =SUMPRODUCT((보유분석!$C$2:$C$801=$D26&"")*(보유분석!$Q$2:$Q$801=1)*($D26<>"")*보유분석!$AM$2:$AM$801) -> 2627.9067 | J26: =IF(E26=0,"",SUMPRODUCT((보유분석!$C$2:$C$801=$D26&"")*(보유분석!$Q$2:$Q$801=1)*($D26<>"")*보유분석!$AV$2:$AV$801)/(E26*1000000)) -> 0.038967811 | K26: =SUMPRODUCT((보유분석!$C$2:$C$801=$D26&"")*(보유분석!$Q$2:$Q$801=1)*($D26<>"")/(COUNTIFS(보유분석!$C$2:$C$801,보유분석!$C$2:$C$801,보유분석!$B$2:$B$801,보유분석!$B$2:$B$801,보유분석!$Q$2:$Q$801,1)+(보유분석!$Q$2:$Q$801<>1))) -> 4
D27: 38088 | E27: =SUMPRODUCT((보유분석!$C$2:$C$801=$D27&"")*(보유분석!$Q$2:$Q$801=1)*($D27<>"")*보유분석!$AA$2:$AA$801) -> 124.56627 | F27: =IF(SUMPRODUCT((보유분석!$C$2:$C$801=$D27&"")*(보유분석!$Q$2:$Q$801=1)*($D27<>"")*보유분석!$BB$2:$BB$801)=0,"",SUMPRODUCT((보유분석!$C$2:$C$801=$D27&"")*(보유분석!$Q$2:$Q$801=1)*($D27<>"")*보유분석!$BA$2:$BA$801)/SUMPRODUCT((보유분석!$C$2:$C$801=$D27&"")*(보유분석!$Q$2:$Q$801=1)*($D27<>"")*보유분석!$BB$2:$BB$801)) -> 5.3442373 | G27: =IF(SUMPRODUCT((보유분석!$C$2:$C$801=$D27&"")*(보유분석!$Q$2:$Q$801=1)*($D27<>"")*보유분석!$BD$2:$BD$801)=0,"",SUMPRODUCT((보유분석!$C$2:$C$801=$D27&"")*(보유분석!$Q$2:$Q$801=1)*($D27<>"")*보유분석!$BC$2:$BC$801)/SUMPRODUCT((보유분석!$C$2:$C$801=$D27&"")*(보유분석!$Q$2:$Q$801=1)*($D27<>"")*보유분석!$BD$2:$BD$801)) -> 47.609006 | H27: =IF(SUMPRODUCT((보유분석!$C$2:$C$801=$D27&"")*(보유분석!$Q$2:$Q$801=1)*($D27<>"")*보유분석!$BF$2:$BF$801)=0,"",SUMPRODUCT((보유분석!$C$2:$C$801=$D27&"")*(보유분석!$Q$2:$Q$801=1)*($D27<>"")*보유분석!$BE$2:$BE$801)/SUMPRODUCT((보유분석!$C$2:$C$801=$D27&"")*(보유분석!$Q$2:$Q$801=1)*($D27<>"")*보유분석!$BF$2:$BF$801)) -> 6.2214607 | I27: =SUMPRODUCT((보유분석!$C$2:$C$801=$D27&"")*(보유분석!$Q$2:$Q$801=1)*($D27<>"")*보유분석!$AM$2:$AM$801) -> 77498.418 | J27: =IF(E27=0,"",SUMPRODUCT((보유분석!$C$2:$C$801=$D27&"")*(보유분석!$Q$2:$Q$801=1)*($D27<>"")*보유분석!$AV$2:$AV$801)/(E27*1000000)) -> 0.053989885 | K27: =SUMPRODUCT((보유분석!$C$2:$C$801=$D27&"")*(보유분석!$Q$2:$Q$801=1)*($D27<>"")/(COUNTIFS(보유분석!$C$2:$C$801,보유분석!$C$2:$C$801,보유분석!$B$2:$B$801,보유분석!$B$2:$B$801,보유분석!$Q$2:$Q$801,1)+(보유분석!$Q$2:$Q$801<>1))) -> 9
D28: 38167 | E28: =SUMPRODUCT((보유분석!$C$2:$C$801=$D28&"")*(보유분석!$Q$2:$Q$801=1)*($D28<>"")*보유분석!$AA$2:$AA$801) -> 11.123963 | F28: =IF(SUMPRODUCT((보유분석!$C$2:$C$801=$D28&"")*(보유분석!$Q$2:$Q$801=1)*($D28<>"")*보유분석!$BB$2:$BB$801)=0,"",SUMPRODUCT((보유분석!$C$2:$C$801=$D28&"")*(보유분석!$Q$2:$Q$801=1)*($D28<>"")*보유분석!$BA$2:$BA$801)/SUMPRODUCT((보유분석!$C$2:$C$801=$D28&"")*(보유분석!$Q$2:$Q$801=1)*($D28<>"")*보유분석!$BB$2:$BB$801)) -> 4.0507118 | G28: =IF(SUMPRODUCT((보유분석!$C$2:$C$801=$D28&"")*(보유분석!$Q$2:$Q$801=1)*($D28<>"")*보유분석!$BD$2:$BD$801)=0,"",SUMPRODUCT((보유분석!$C$2:$C$801=$D28&"")*(보유분석!$Q$2:$Q$801=1)*($D28<>"")*보유분석!$BC$2:$BC$801)/SUMPRODUCT((보유분석!$C$2:$C$801=$D28&"")*(보유분석!$Q$2:$Q$801=1)*($D28<>"")*보유분석!$BD$2:$BD$801)) -> 75.323616 | H28: =IF(SUMPRODUCT((보유분석!$C$2:$C$801=$D28&"")*(보유분석!$Q$2:$Q$801=1)*($D28<>"")*보유분석!$BF$2:$BF$801)=0,"",SUMPRODUCT((보유분석!$C$2:$C$801=$D28&"")*(보유분석!$Q$2:$Q$801=1)*($D28<>"")*보유분석!$BE$2:$BE$801)/SUMPRODUCT((보유분석!$C$2:$C$801=$D28&"")*(보유분석!$Q$2:$Q$801=1)*($D28<>"")*보유분석!$BF$2:$BF$801)) -> 2.5602482 | I28: =SUMPRODUCT((보유분석!$C$2:$C$801=$D28&"")*(보유분석!$Q$2:$Q$801=1)*($D28<>"")*보유분석!$AM$2:$AM$801) -> 2848.0105 | J28: =IF(E28=0,"",SUMPRODUCT((보유분석!$C$2:$C$801=$D28&"")*(보유분석!$Q$2:$Q$801=1)*($D28<>"")*보유분석!$AV$2:$AV$801)/(E28*1000000)) -> 0.040507118 | K28: =SUMPRODUCT((보유분석!$C$2:$C$801=$D28&"")*(보유분석!$Q$2:$Q$801=1)*($D28<>"")/(COUNTIFS(보유분석!$C$2:$C$801,보유분석!$C$2:$C$801,보유분석!$B$2:$B$801,보유분석!$B$2:$B$801,보유분석!$Q$2:$Q$801,1)+(보유분석!$Q$2:$Q$801<>1))) -> 3
D29: 38168 | E29: =SUMPRODUCT((보유분석!$C$2:$C$801=$D29&"")*(보유분석!$Q$2:$Q$801=1)*($D29<>"")*보유분석!$AA$2:$AA$801) -> 4.9279668 | F29: =IF(SUMPRODUCT((보유분석!$C$2:$C$801=$D29&"")*(보유분석!$Q$2:$Q$801=1)*($D29<>"")*보유분석!$BB$2:$BB$801)=0,"",SUMPRODUCT((보유분석!$C$2:$C$801=$D29&"")*(보유분석!$Q$2:$Q$801=1)*($D29<>"")*보유분석!$BA$2:$BA$801)/SUMPRODUCT((보유분석!$C$2:$C$801=$D29&"")*(보유분석!$Q$2:$Q$801=1)*($D29<>"")*보유분석!$BB$2:$BB$801)) -> 5.680743 | G29: =IF(SUMPRODUCT((보유분석!$C$2:$C$801=$D29&"")*(보유분석!$Q$2:$Q$801=1)*($D29<>"")*보유분석!$BD$2:$BD$801)=0,"",SUMPRODUCT((보유분석!$C$2:$C$801=$D29&"")*(보유분석!$Q$2:$Q$801=1)*($D29<>"")*보유분석!$BC$2:$BC$801)/SUMPRODUCT((보유분석!$C$2:$C$801=$D29&"")*(보유분석!$Q$2:$Q$801=1)*($D29<>"")*보유분석!$BD$2:$BD$801)) -> 70.181262 | H29: =IF(SUMPRODUCT((보유분석!$C$2:$C$801=$D29&"")*(보유분석!$Q$2:$Q$801=1)*($D29<>"")*보유분석!$BF$2:$BF$801)=0,"",SUMPRODUCT((보유분석!$C$2:$C$801=$D29&"")*(보유분석!$Q$2:$Q$801=1)*($D29<>"")*보유분석!$BE$2:$BE$801)/SUMPRODUCT((보유분석!$C$2:$C$801=$D29&"")*(보유분석!$Q$2:$Q$801=1)*($D29<>"")*보유분석!$BF$2:$BF$801)) -> 3.6540037 | I29: =SUMPRODUCT((보유분석!$C$2:$C$801=$D29&"")*(보유분석!$Q$2:$Q$801=1)*($D29<>"")*보유분석!$AM$2:$AM$801) -> 1800.6809 | J29: =IF(E29=0,"",SUMPRODUCT((보유분석!$C$2:$C$801=$D29&"")*(보유분석!$Q$2:$Q$801=1)*($D29<>"")*보유분석!$AV$2:$AV$801)/(E29*1000000)) -> 0.058441678 | K29: =SUMPRODUCT((보유분석!$C$2:$C$801=$D29&"")*(보유분석!$Q$2:$Q$801=1)*($D29<>"")/(COUNTIFS(보유분석!$C$2:$C$801,보유분석!$C$2:$C$801,보유분석!$B$2:$B$801,보유분석!$B$2:$B$801,보유분석!$Q$2:$Q$801,1)+(보유분석!$Q$2:$Q$801<>1))) -> 2
D30: 42003 | E30: =SUMPRODUCT((보유분석!$C$2:$C$801=$D30&"")*(보유분석!$Q$2:$Q$801=1)*($D30<>"")*보유분석!$AA$2:$AA$801) -> 305.96496 | F30: =IF(SUMPRODUCT((보유분석!$C$2:$C$801=$D30&"")*(보유분석!$Q$2:$Q$801=1)*($D30<>"")*보유분석!$BB$2:$BB$801)=0,"",SUMPRODUCT((보유분석!$C$2:$C$801=$D30&"")*(보유분석!$Q$2:$Q$801=1)*($D30<>"")*보유분석!$BA$2:$BA$801)/SUMPRODUCT((보유분석!$C$2:$C$801=$D30&"")*(보유분석!$Q$2:$Q$801=1)*($D30<>"")*보유분석!$BB$2:$BB$801)) -> 5.2661961 | G30: =IF(SUMPRODUCT((보유분석!$C$2:$C$801=$D30&"")*(보유분석!$Q$2:$Q$801=1)*($D30<>"")*보유분석!$BD$2:$BD$801)=0,"",SUMPRODUCT((보유분석!$C$2:$C$801=$D30&"")*(보유분석!$Q$2:$Q$801=1)*($D30<>"")*보유분석!$BC$2:$BC$801)/SUMPRODUCT((보유분석!$C$2:$C$801=$D30&"")*(보유분석!$Q$2:$Q$801=1)*($D30<>"")*보유분석!$BD$2:$BD$801)) -> 24.777927 | H30: =IF(SUMPRODUCT((보유분석!$C$2:$C$801=$D30&"")*(보유분석!$Q$2:$Q$801=1)*($D30<>"")*보유분석!$BF$2:$BF$801)=0,"",SUMPRODUCT((보유분석!$C$2:$C$801=$D30&"")*(보유분석!$Q$2:$Q$801=1)*($D30<>"")*보유분석!$BE$2:$BE$801)/SUMPRODUCT((보유분석!$C$2:$C$801=$D30&"")*(보유분석!$Q$2:$Q$801=1)*($D30<>"")*보유분석!$BF$2:$BF$801)) -> 2.8420326 | I30: =SUMPRODUCT((보유분석!$C$2:$C$801=$D30&"")*(보유분석!$Q$2:$Q$801=1)*($D30<>"")*보유분석!$AM$2:$AM$801) -> 86956.238 | J30: =IF(E30=0,"",SUMPRODUCT((보유분석!$C$2:$C$801=$D30&"")*(보유분석!$Q$2:$Q$801=1)*($D30<>"")*보유분석!$AV$2:$AV$801)/(E30*1000000)) -> 0.053847272 | K30: =SUMPRODUCT((보유분석!$C$2:$C$801=$D30&"")*(보유분석!$Q$2:$Q$801=1)*($D30<>"")/(COUNTIFS(보유분석!$C$2:$C$801,보유분석!$C$2:$C$801,보유분석!$B$2:$B$801,보유분석!$B$2:$B$801,보유분석!$Q$2:$Q$801,1)+(보유분석!$Q$2:$Q$801<>1))) -> 81
D31: 42006 | E31: =SUMPRODUCT((보유분석!$C$2:$C$801=$D31&"")*(보유분석!$Q$2:$Q$801=1)*($D31<>"")*보유분석!$AA$2:$AA$801) -> 34.436675 | F31: =IF(SUMPRODUCT((보유분석!$C$2:$C$801=$D31&"")*(보유분석!$Q$2:$Q$801=1)*($D31<>"")*보유분석!$BB$2:$BB$801)=0,"",SUMPRODUCT((보유분석!$C$2:$C$801=$D31&"")*(보유분석!$Q$2:$Q$801=1)*($D31<>"")*보유분석!$BA$2:$BA$801)/SUMPRODUCT((보유분석!$C$2:$C$801=$D31&"")*(보유분석!$Q$2:$Q$801=1)*($D31<>"")*보유분석!$BB$2:$BB$801)) -> 2.1514289 | G31: =IF(SUMPRODUCT((보유분석!$C$2:$C$801=$D31&"")*(보유분석!$Q$2:$Q$801=1)*($D31<>"")*보유분석!$BD$2:$BD$801)=0,"",SUMPRODUCT((보유분석!$C$2:$C$801=$D31&"")*(보유분석!$Q$2:$Q$801=1)*($D31<>"")*보유분석!$BC$2:$BC$801)/SUMPRODUCT((보유분석!$C$2:$C$801=$D31&"")*(보유분석!$Q$2:$Q$801=1)*($D31<>"")*보유분석!$BD$2:$BD$801)) -> 37.267847 | H31: =IF(SUMPRODUCT((보유분석!$C$2:$C$801=$D31&"")*(보유분석!$Q$2:$Q$801=1)*($D31<>"")*보유분석!$BF$2:$BF$801)=0,"",SUMPRODUCT((보유분석!$C$2:$C$801=$D31&"")*(보유분석!$Q$2:$Q$801=1)*($D31<>"")*보유분석!$BE$2:$BE$801)/SUMPRODUCT((보유분석!$C$2:$C$801=$D31&"")*(보유분석!$Q$2:$Q$801=1)*($D31<>"")*보유분석!$BF$2:$BF$801)) -> 1.5502998 | I31: =SUMPRODUCT((보유분석!$C$2:$C$801=$D31&"")*(보유분석!$Q$2:$Q$801=1)*($D31<>"")*보유분석!$AM$2:$AM$801) -> 5338.7171 | J31: =IF(E31=0,"",SUMPRODUCT((보유분석!$C$2:$C$801=$D31&"")*(보유분석!$Q$2:$Q$801=1)*($D31<>"")*보유분석!$AV$2:$AV$801)/(E31*1000000)) -> 0.021514289 | K31: =SUMPRODUCT((보유분석!$C$2:$C$801=$D31&"")*(보유분석!$Q$2:$Q$801=1)*($D31<>"")/(COUNTIFS(보유분석!$C$2:$C$801,보유분석!$C$2:$C$801,보유분석!$B$2:$B$801,보유분석!$B$2:$B$801,보유분석!$Q$2:$Q$801,1)+(보유분석!$Q$2:$Q$801<>1))) -> 5
D32: 42011 | E32: =SUMPRODUCT((보유분석!$C$2:$C$801=$D32&"")*(보유분석!$Q$2:$Q$801=1)*($D32<>"")*보유분석!$AA$2:$AA$801) -> 15.861448 | F32: =IF(SUMPRODUCT((보유분석!$C$2:$C$801=$D32&"")*(보유분석!$Q$2:$Q$801=1)*($D32<>"")*보유분석!$BB$2:$BB$801)=0,"",SUMPRODUCT((보유분석!$C$2:$C$801=$D32&"")*(보유분석!$Q$2:$Q$801=1)*($D32<>"")*보유분석!$BA$2:$BA$801)/SUMPRODUCT((보유분석!$C$2:$C$801=$D32&"")*(보유분석!$Q$2:$Q$801=1)*($D32<>"")*보유분석!$BB$2:$BB$801)) -> 5.3930465 | G32: =IF(SUMPRODUCT((보유분석!$C$2:$C$801=$D32&"")*(보유분석!$Q$2:$Q$801=1)*($D32<>"")*보유분석!$BD$2:$BD$801)=0,"",SUMPRODUCT((보유분석!$C$2:$C$801=$D32&"")*(보유분석!$Q$2:$Q$801=1)*($D32<>"")*보유분석!$BC$2:$BC$801)/SUMPRODUCT((보유분석!$C$2:$C$801=$D32&"")*(보유분석!$Q$2:$Q$801=1)*($D32<>"")*보유분석!$BD$2:$BD$801)) | H32: =IF(SUMPRODUCT((보유분석!$C$2:$C$801=$D32&"")*(보유분석!$Q$2:$Q$801=1)*($D32<>"")*보유분석!$BF$2:$BF$801)=0,"",SUMPRODUCT((보유분석!$C$2:$C$801=$D32&"")*(보유분석!$Q$2:$Q$801=1)*($D32<>"")*보유분석!$BE$2:$BE$801)/SUMPRODUCT((보유분석!$C$2:$C$801=$D32&"")*(보유분석!$Q$2:$Q$801=1)*($D32<>"")*보유분석!$BF$2:$BF$801)) -> 4.1168512 | I32: =SUMPRODUCT((보유분석!$C$2:$C$801=$D32&"")*(보유분석!$Q$2:$Q$801=1)*($D32<>"")*보유분석!$AM$2:$AM$801) -> 6529.9223 | J32: =IF(E32=0,"",SUMPRODUCT((보유분석!$C$2:$C$801=$D32&"")*(보유분석!$Q$2:$Q$801=1)*($D32<>"")*보유분석!$AV$2:$AV$801)/(E32*1000000)) -> 0.053930465 | K32: =SUMPRODUCT((보유분석!$C$2:$C$801=$D32&"")*(보유분석!$Q$2:$Q$801=1)*($D32<>"")/(COUNTIFS(보유분석!$C$2:$C$801,보유분석!$C$2:$C$801,보유분석!$B$2:$B$801,보유분석!$B$2:$B$801,보유분석!$Q$2:$Q$801,1)+(보유분석!$Q$2:$Q$801<>1))) -> 4
E33: =SUMPRODUCT((보유분석!$C$2:$C$801=$D33&"")*(보유분석!$Q$2:$Q$801=1)*($D33<>"")*보유분석!$AA$2:$AA$801) -> 0 | F33: =IF(SUMPRODUCT((보유분석!$C$2:$C$801=$D33&"")*(보유분석!$Q$2:$Q$801=1)*($D33<>"")*보유분석!$BB$2:$BB$801)=0,"",SUMPRODUCT((보유분석!$C$2:$C$801=$D33&"")*(보유분석!$Q$2:$Q$801=1)*($D33<>"")*보유분석!$BA$2:$BA$801)/SUMPRODUCT((보유분석!$C$2:$C$801=$D33&"")*(보유분석!$Q$2:$Q$801=1)*($D33<>"")*보유분석!$BB$2:$BB$801)) | G33: =IF(SUMPRODUCT((보유분석!$C$2:$C$801=$D33&"")*(보유분석!$Q$2:$Q$801=1)*($D33<>"")*보유분석!$BD$2:$BD$801)=0,"",SUMPRODUCT((보유분석!$C$2:$C$801=$D33&"")*(보유분석!$Q$2:$Q$801=1)*($D33<>"")*보유분석!$BC$2:$BC$801)/SUMPRODUCT((보유분석!$C$2:$C$801=$D33&"")*(보유분석!$Q$2:$Q$801=1)*($D33<>"")*보유분석!$BD$2:$BD$801)) | H33: =IF(SUMPRODUCT((보유분석!$C$2:$C$801=$D33&"")*(보유분석!$Q$2:$Q$801=1)*($D33<>"")*보유분석!$BF$2:$BF$801)=0,"",SUMPRODUCT((보유분석!$C$2:$C$801=$D33&"")*(보유분석!$Q$2:$Q$801=1)*($D33<>"")*보유분석!$BE$2:$BE$801)/SUMPRODUCT((보유분석!$C$2:$C$801=$D33&"")*(보유분석!$Q$2:$Q$801=1)*($D33<>"")*보유분석!$BF$2:$BF$801)) | I33: =SUMPRODUCT((보유분석!$C$2:$C$801=$D33&"")*(보유분석!$Q$2:$Q$801=1)*($D33<>"")*보유분석!$AM$2:$AM$801) -> 0 | J33: =IF(E33=0,"",SUMPRODUCT((보유분석!$C$2:$C$801=$D33&"")*(보유분석!$Q$2:$Q$801=1)*($D33<>"")*보유분석!$AV$2:$AV$801)/(E33*1000000)) | K33: =SUMPRODUCT((보유분석!$C$2:$C$801=$D33&"")*(보유분석!$Q$2:$Q$801=1)*($D33<>"")/(COUNTIFS(보유분석!$C$2:$C$801,보유분석!$C$2:$C$801,보유분석!$B$2:$B$801,보유분석!$B$2:$B$801,보유분석!$Q$2:$Q$801,1)+(보유분석!$Q$2:$Q$801<>1))) -> 0
E34: =SUMPRODUCT((보유분석!$C$2:$C$801=$D34&"")*(보유분석!$Q$2:$Q$801=1)*($D34<>"")*보유분석!$AA$2:$AA$801) -> 0 | F34: =IF(SUMPRODUCT((보유분석!$C$2:$C$801=$D34&"")*(보유분석!$Q$2:$Q$801=1)*($D34<>"")*보유분석!$BB$2:$BB$801)=0,"",SUMPRODUCT((보유분석!$C$2:$C$801=$D34&"")*(보유분석!$Q$2:$Q$801=1)*($D34<>"")*보유분석!$BA$2:$BA$801)/SUMPRODUCT((보유분석!$C$2:$C$801=$D34&"")*(보유분석!$Q$2:$Q$801=1)*($D34<>"")*보유분석!$BB$2:$BB$801)) | G34: =IF(SUMPRODUCT((보유분석!$C$2:$C$801=$D34&"")*(보유분석!$Q$2:$Q$801=1)*($D34<>"")*보유분석!$BD$2:$BD$801)=0,"",SUMPRODUCT((보유분석!$C$2:$C$801=$D34&"")*(보유분석!$Q$2:$Q$801=1)*($D34<>"")*보유분석!$BC$2:$BC$801)/SUMPRODUCT((보유분석!$C$2:$C$801=$D34&"")*(보유분석!$Q$2:$Q$801=1)*($D34<>"")*보유분석!$BD$2:$BD$801)) | H34: =IF(SUMPRODUCT((보유분석!$C$2:$C$801=$D34&"")*(보유분석!$Q$2:$Q$801=1)*($D34<>"")*보유분석!$BF$2:$BF$801)=0,"",SUMPRODUCT((보유분석!$C$2:$C$801=$D34&"")*(보유분석!$Q$2:$Q$801=1)*($D34<>"")*보유분석!$BE$2:$BE$801)/SUMPRODUCT((보유분석!$C$2:$C$801=$D34&"")*(보유분석!$Q$2:$Q$801=1)*($D34<>"")*보유분석!$BF$2:$BF$801)) | I34: =SUMPRODUCT((보유분석!$C$2:$C$801=$D34&"")*(보유분석!$Q$2:$Q$801=1)*($D34<>"")*보유분석!$AM$2:$AM$801) -> 0 | J34: =IF(E34=0,"",SUMPRODUCT((보유분석!$C$2:$C$801=$D34&"")*(보유분석!$Q$2:$Q$801=1)*($D34<>"")*보유분석!$AV$2:$AV$801)/(E34*1000000)) | K34: =SUMPRODUCT((보유분석!$C$2:$C$801=$D34&"")*(보유분석!$Q$2:$Q$801=1)*($D34<>"")/(COUNTIFS(보유분석!$C$2:$C$801,보유분석!$C$2:$C$801,보유분석!$B$2:$B$801,보유분석!$B$2:$B$801,보유분석!$Q$2:$Q$801,1)+(보유분석!$Q$2:$Q$801<>1))) -> 0
E35: =SUMPRODUCT((보유분석!$C$2:$C$801=$D35&"")*(보유분석!$Q$2:$Q$801=1)*($D35<>"")*보유분석!$AA$2:$AA$801) -> 0 | F35: =IF(SUMPRODUCT((보유분석!$C$2:$C$801=$D35&"")*(보유분석!$Q$2:$Q$801=1)*($D35<>"")*보유분석!$BB$2:$BB$801)=0,"",SUMPRODUCT((보유분석!$C$2:$C$801=$D35&"")*(보유분석!$Q$2:$Q$801=1)*($D35<>"")*보유분석!$BA$2:$BA$801)/SUMPRODUCT((보유분석!$C$2:$C$801=$D35&"")*(보유분석!$Q$2:$Q$801=1)*($D35<>"")*보유분석!$BB$2:$BB$801)) | G35: =IF(SUMPRODUCT((보유분석!$C$2:$C$801=$D35&"")*(보유분석!$Q$2:$Q$801=1)*($D35<>"")*보유분석!$BD$2:$BD$801)=0,"",SUMPRODUCT((보유분석!$C$2:$C$801=$D35&"")*(보유분석!$Q$2:$Q$801=1)*($D35<>"")*보유분석!$BC$2:$BC$801)/SUMPRODUCT((보유분석!$C$2:$C$801=$D35&"")*(보유분석!$Q$2:$Q$801=1)*($D35<>"")*보유분석!$BD$2:$BD$801)) | H35: =IF(SUMPRODUCT((보유분석!$C$2:$C$801=$D35&"")*(보유분석!$Q$2:$Q$801=1)*($D35<>"")*보유분석!$BF$2:$BF$801)=0,"",SUMPRODUCT((보유분석!$C$2:$C$801=$D35&"")*(보유분석!$Q$2:$Q$801=1)*($D35<>"")*보유분석!$BE$2:$BE$801)/SUMPRODUCT((보유분석!$C$2:$C$801=$D35&"")*(보유분석!$Q$2:$Q$801=1)*($D35<>"")*보유분석!$BF$2:$BF$801)) | I35: =SUMPRODUCT((보유분석!$C$2:$C$801=$D35&"")*(보유분석!$Q$2:$Q$801=1)*($D35<>"")*보유분석!$AM$2:$AM$801) -> 0 | J35: =IF(E35=0,"",SUMPRODUCT((보유분석!$C$2:$C$801=$D35&"")*(보유분석!$Q$2:$Q$801=1)*($D35<>"")*보유분석!$AV$2:$AV$801)/(E35*1000000)) | K35: =SUMPRODUCT((보유분석!$C$2:$C$801=$D35&"")*(보유분석!$Q$2:$Q$801=1)*($D35<>"")/(COUNTIFS(보유분석!$C$2:$C$801,보유분석!$C$2:$C$801,보유분석!$B$2:$B$801,보유분석!$B$2:$B$801,보유분석!$Q$2:$Q$801,1)+(보유분석!$Q$2:$Q$801<>1))) -> 0
E36: =SUMPRODUCT((보유분석!$C$2:$C$801=$D36&"")*(보유분석!$Q$2:$Q$801=1)*($D36<>"")*보유분석!$AA$2:$AA$801) -> 0 | F36: =IF(SUMPRODUCT((보유분석!$C$2:$C$801=$D36&"")*(보유분석!$Q$2:$Q$801=1)*($D36<>"")*보유분석!$BB$2:$BB$801)=0,"",SUMPRODUCT((보유분석!$C$2:$C$801=$D36&"")*(보유분석!$Q$2:$Q$801=1)*($D36<>"")*보유분석!$BA$2:$BA$801)/SUMPRODUCT((보유분석!$C$2:$C$801=$D36&"")*(보유분석!$Q$2:$Q$801=1)*($D36<>"")*보유분석!$BB$2:$BB$801)) | G36: =IF(SUMPRODUCT((보유분석!$C$2:$C$801=$D36&"")*(보유분석!$Q$2:$Q$801=1)*($D36<>"")*보유분석!$BD$2:$BD$801)=0,"",SUMPRODUCT((보유분석!$C$2:$C$801=$D36&"")*(보유분석!$Q$2:$Q$801=1)*($D36<>"")*보유분석!$BC$2:$BC$801)/SUMPRODUCT((보유분석!$C$2:$C$801=$D36&"")*(보유분석!$Q$2:$Q$801=1)*($D36<>"")*보유분석!$BD$2:$BD$801)) | H36: =IF(SUMPRODUCT((보유분석!$C$2:$C$801=$D36&"")*(보유분석!$Q$2:$Q$801=1)*($D36<>"")*보유분석!$BF$2:$BF$801)=0,"",SUMPRODUCT((보유분석!$C$2:$C$801=$D36&"")*(보유분석!$Q$2:$Q$801=1)*($D36<>"")*보유분석!$BE$2:$BE$801)/SUMPRODUCT((보유분석!$C$2:$C$801=$D36&"")*(보유분석!$Q$2:$Q$801=1)*($D36<>"")*보유분석!$BF$2:$BF$801)) | I36: =SUMPRODUCT((보유분석!$C$2:$C$801=$D36&"")*(보유분석!$Q$2:$Q$801=1)*($D36<>"")*보유분석!$AM$2:$AM$801) -> 0 | J36: =IF(E36=0,"",SUMPRODUCT((보유분석!$C$2:$C$801=$D36&"")*(보유분석!$Q$2:$Q$801=1)*($D36<>"")*보유분석!$AV$2:$AV$801)/(E36*1000000)) | K36: =SUMPRODUCT((보유분석!$C$2:$C$801=$D36&"")*(보유분석!$Q$2:$Q$801=1)*($D36<>"")/(COUNTIFS(보유분석!$C$2:$C$801,보유분석!$C$2:$C$801,보유분석!$B$2:$B$801,보유분석!$B$2:$B$801,보유분석!$Q$2:$Q$801,1)+(보유분석!$Q$2:$Q$801<>1))) -> 0

Sheet 버킷분석
A1: 버킷별 포트폴리오 분해 (설정의 펀드 선택 반영, 평가금액 기준)
A2: O열 목표비중은 직접 입력(노란 칸). J열 = (G-spread + 롤다운) ÷ 크레딧 듀레이션. Q열 = 스프레드 쇼크 손실(차등·비례 반영)
A4: ■ 만기 구간 (잔존만기)
A5: 구분 | B5: 평가금액($M) | C5: 비중 | D5: DV01($/bp) | E5: DV01비중 | F5: 가중YTM(%) | G5: 포트대비(bp) | H5: 가중G-spread(bp) | I5: 가중듀레이션 | J5: 손익분기 확대폭(bp) 스프레드+롤다운 | K5: 1Y기대수익률(%) | L5: 평가손익($) | M5: Cheap 보유수 | N5: Rich 보유수 | O5: 목표비중(입력) | P5: 갭(목표-현재) | Q5: 스프레드쇼크 손실($) | R5: 손실비중 | S5: └ 롤다운 기여(bp) | T5: G-spread 커버리지
A6: 1년 이하 | B6: =SUMIFS(보유분석!$AA$2:$AA$801,보유분석!$V$2:$V$801,$A6,보유분석!$AC$2:$AC$801,1) -> 79.051414 | C6: =IF(SUMIFS(보유분석!$AA$2:$AA$801,보유분석!$AC$2:$AC$801,1)=0,0,B6/SUMIFS(보유분석!$AA$2:$AA$801,보유분석!$AC$2:$AC$801,1)) -> 0.056088754 | D6: =SUMIFS(보유분석!$AM$2:$AM$801,보유분석!$V$2:$V$801,$A6,보유분석!$AC$2:$AC$801,1) -> 1280.3866 | E6: =IF(SUMIFS(보유분석!$AM$2:$AM$801,보유분석!$AC$2:$AC$801,1)=0,0,D6/SUMIFS(보유분석!$AM$2:$AM$801,보유분석!$AC$2:$AC$801,1)) -> 0.0033763405 | F6: =IF(SUMIFS(보유분석!$BB$2:$BB$801,보유분석!$V$2:$V$801,$A6,보유분석!$AC$2:$AC$801,1)=0,"",SUMIFS(보유분석!$BA$2:$BA$801,보유분석!$V$2:$V$801,$A6,보유분석!$AC$2:$AC$801,1)/SUMIFS(보유분석!$BB$2:$BB$801,보유분석!$V$2:$V$801,$A6,보유분석!$AC$2:$AC$801,1)) -> 5.2143793 | G6: =IF(F6="","",(F6-(SUMIFS(보유분석!$BA$2:$BA$801,보유분석!$AC$2:$AC$801,1)/SUMIFS(보유분석!$BB$2:$BB$801,보유분석!$AC$2:$AC$801,1)))*100) -> -44.56565 | H6: =IF(SUMIFS(보유분석!$BD$2:$BD$801,보유분석!$V$2:$V$801,$A6,보유분석!$AC$2:$AC$801,1)=0,"",SUMIFS(보유분석!$BC$2:$BC$801,보유분석!$V$2:$V$801,$A6,보유분석!$AC$2:$AC$801,1)/SUMIFS(보유분석!$BD$2:$BD$801,보유분석!$V$2:$V$801,$A6,보유분석!$AC$2:$AC$801,1)) -> -4.5997652 | I6: =IF(SUMIFS(보유분석!$BF$2:$BF$801,보유분석!$V$2:$V$801,$A6,보유분석!$AC$2:$AC$801,1)=0,"",SUMIFS(보유분석!$BE$2:$BE$801,보유분석!$V$2:$V$801,$A6,보유분석!$AC$2:$AC$801,1)/SUMIFS(보유분석!$BF$2:$BF$801,보유분석!$V$2:$V$801,$A6,보유분석!$AC$2:$AC$801,1)) -> 0.16196884 | J6: =IF(SUMIFS(보유분석!$BG$2:$BG$801,보유분석!$V$2:$V$801,$A6,보유분석!$AC$2:$AC$801,1)=0,"",(SUMIFS(보유분석!$BC$2:$BC$801,보유분석!$V$2:$V$801,$A6,보유분석!$AC$2:$AC$801,1)+SUMIFS(보유분석!$BH$2:$BH$801,보유분석!$V$2:$V$801,$A6,보유분석!$AC$2:$AC$801,1))/SUMIFS(보유분석!$BG$2:$BG$801,보유분석!$V$2:$V$801,$A6,보유분석!$AC$2:$AC$801,1)) -> -24.8657 | K6: =IF(B6=0,"",SUMIFS(보유분석!$AV$2:$AV$801,보유분석!$V$2:$V$801,$A6,보유분석!$AC$2:$AC$801,1)/(B6*1000000)) -> 0.052143793 | L6: =SUMIFS(보유분석!$AP$2:$AP$801,보유분석!$V$2:$V$801,$A6,보유분석!$AC$2:$AC$801,1) -> -915055.96 | M6: =COUNTIFS(보유분석!$V$2:$V$801,$A6,보유분석!$AR$2:$AR$801,"Cheap",보유분석!$AC$2:$AC$801,1) -> 0 | N6: =COUNTIFS(보유분석!$V$2:$V$801,$A6,보유분석!$AR$2:$AR$801,"Rich",보유분석!$AC$2:$AC$801,1) -> 1 | P6: =IF(O6="","",O6-C6) | Q6: =-SUMIFS(보유분석!$AZ$2:$AZ$801,보유분석!$V$2:$V$801,$A6,보유분석!$AC$2:$AC$801,1)*설정!$C$10 -> -22052.083 | R6: =IF((-SUMIFS(보유분석!$AZ$2:$AZ$801,보유분석!$AC$2:$AC$801,1)*설정!$C$10)=0,0,Q6/(-SUMIFS(보유분석!$AZ$2:$AZ$801,보유분석!$AC$2:$AC$801,1)*설정!$C$10)) -> 0.0021668496 | S6: =IF(SUMIFS(보유분석!$BG$2:$BG$801,보유분석!$V$2:$V$801,$A6,보유분석!$AC$2:$AC$801,1)=0,"",SUMIFS(보유분석!$BH$2:$BH$801,보유분석!$V$2:$V$801,$A6,보유분석!$AC$2:$AC$801,1)/SUMIFS(보유분석!$BG$2:$BG$801,보유분석!$V$2:$V$801,$A6,보유분석!$AC$2:$AC$801,1)) -> 0 | T6: =IF(SUMIFS(보유분석!$BI$2:$BI$801,보유분석!$V$2:$V$801,$A6,보유분석!$AC$2:$AC$801,1)=0,"",SUMIFS(보유분석!$BD$2:$BD$801,보유분석!$V$2:$V$801,$A6,보유분석!$AC$2:$AC$801,1)/SUMIFS(보유분석!$BI$2:$BI$801,보유분석!$V$2:$V$801,$A6,보유분석!$AC$2:$AC$801,1)) -> 0.8728315
A7: 1-2년 | B7: =SUMIFS(보유분석!$AA$2:$AA$801,보유분석!$V$2:$V$801,$A7,보유분석!$AC$2:$AC$801,1) -> 139.69334 | C7: =IF(SUMIFS(보유분석!$AA$2:$AA$801,보유분석!$AC$2:$AC$801,1)=0,0,B7/SUMIFS(보유분석!$AA$2:$AA$801,보유분석!$AC$2:$AC$801,1)) -> 0.099115562 | D7: =SUMIFS(보유분석!$AM$2:$AM$801,보유분석!$V$2:$V$801,$A7,보유분석!$AC$2:$AC$801,1) -> 20773.224 | E7: =IF(SUMIFS(보유분석!$AM$2:$AM$801,보유분석!$AC$2:$AC$801,1)=0,0,D7/SUMIFS(보유분석!$AM$2:$AM$801,보유분석!$AC$2:$AC$801,1)) -> 0.054778362 | F7: =IF(SUMIFS(보유분석!$BB$2:$BB$801,보유분석!$V$2:$V$801,$A7,보유분석!$AC$2:$AC$801,1)=0,"",SUMIFS(보유분석!$BA$2:$BA$801,보유분석!$V$2:$V$801,$A7,보유분석!$AC$2:$AC$801,1)/SUMIFS(보유분석!$BB$2:$BB$801,보유분석!$V$2:$V$801,$A7,보유분석!$AC$2:$AC$801,1)) -> 5.4787395 | G7: =IF(F7="","",(F7-(SUMIFS(보유분석!$BA$2:$BA$801,보유분석!$AC$2:$AC$801,1)/SUMIFS(보유분석!$BB$2:$BB$801,보유분석!$AC$2:$AC$801,1)))*100) -> -18.129635 | H7: =IF(SUMIFS(보유분석!$BD$2:$BD$801,보유분석!$V$2:$V$801,$A7,보유분석!$AC$2:$AC$801,1)=0,"",SUMIFS(보유분석!$BC$2:$BC$801,보유분석!$V$2:$V$801,$A7,보유분석!$AC$2:$AC$801,1)/SUMIFS(보유분석!$BD$2:$BD$801,보유분석!$V$2:$V$801,$A7,보유분석!$AC$2:$AC$801,1)) -> 59.964449 | I7: =IF(SUMIFS(보유분석!$BF$2:$BF$801,보유분석!$V$2:$V$801,$A7,보유분석!$AC$2:$AC$801,1)=0,"",SUMIFS(보유분석!$BE$2:$BE$801,보유분석!$V$2:$V$801,$A7,보유분석!$AC$2:$AC$801,1)/SUMIFS(보유분석!$BF$2:$BF$801,보유분석!$V$2:$V$801,$A7,보유분석!$AC$2:$AC$801,1)) -> 1.487059 | J7: =IF(SUMIFS(보유분석!$BG$2:$BG$801,보유분석!$V$2:$V$801,$A7,보유분석!$AC$2:$AC$801,1)=0,"",(SUMIFS(보유분석!$BC$2:$BC$801,보유분석!$V$2:$V$801,$A7,보유분석!$AC$2:$AC$801,1)+SUMIFS(보유분석!$BH$2:$BH$801,보유분석!$V$2:$V$801,$A7,보유분석!$AC$2:$AC$801,1))/SUMIFS(보유분석!$BG$2:$BG$801,보유분석!$V$2:$V$801,$A7,보유분석!$AC$2:$AC$801,1)) -> 44.633498 | K7: =IF(B7=0,"",SUMIFS(보유분석!$AV$2:$AV$801,보유분석!$V$2:$V$801,$A7,보유분석!$AC$2:$AC$801,1)/(B7*1000000)) -> 0.055425565 | L7: =SUMIFS(보유분석!$AP$2:$AP$801,보유분석!$V$2:$V$801,$A7,보유분석!$AC$2:$AC$801,1) -> -2715439.1 | M7: =COUNTIFS(보유분석!$V$2:$V$801,$A7,보유분석!$AR$2:$AR$801,"Cheap",보유분석!$AC$2:$AC$801,1) -> 1 | N7: =COUNTIFS(보유분석!$V$2:$V$801,$A7,보유분석!$AR$2:$AR$801,"Rich",보유분석!$AC$2:$AC$801,1) -> 0 | P7: =IF(O7="","",O7-C7) | Q7: =-SUMIFS(보유분석!$AZ$2:$AZ$801,보유분석!$V$2:$V$801,$A7,보유분석!$AC$2:$AC$801,1)*설정!$C$10 -> -477954.3 | R7: =IF((-SUMIFS(보유분석!$AZ$2:$AZ$801,보유분석!$AC$2:$AC$801,1)*설정!$C$10)=0,0,Q7/(-SUMIFS(보유분석!$AZ$2:$AZ$801,보유분석!$AC$2:$AC$801,1)*설정!$C$10)) -> 0.046964047 | S7: =IF(SUMIFS(보유분석!$BG$2:$BG$801,보유분석!$V$2:$V$801,$A7,보유분석!$AC$2:$AC$801,1)=0,"",SUMIFS(보유분석!$BH$2:$BH$801,보유분석!$V$2:$V$801,$A7,보유분석!$AC$2:$AC$801,1)/SUMIFS(보유분석!$BG$2:$BG$801,보유분석!$V$2:$V$801,$A7,보유분석!$AC$2:$AC$801,1)) -> 4.3206979 | T7: =IF(SUMIFS(보유분석!$BI$2:$BI$801,보유분석!$V$2:$V$801,$A7,보유분석!$AC$2:$AC$801,1)=0,"",SUMIFS(보유분석!$BD$2:$BD$801,보유분석!$V$2:$V$801,$A7,보유분석!$AC$2:$AC$801,1)/SUMIFS(보유분석!$BI$2:$BI$801,보유분석!$V$2:$V$801,$A7,보유분석!$AC$2:$AC$801,1)) -> 1
A8: 2-3년 | B8: =SUMIFS(보유분석!$AA$2:$AA$801,보유분석!$V$2:$V$801,$A8,보유분석!$AC$2:$AC$801,1) -> 508.38991 | C8: =IF(SUMIFS(보유분석!$AA$2:$AA$801,보유분석!$AC$2:$AC$801,1)=0,0,B8/SUMIFS(보유분석!$AA$2:$AA$801,보유분석!$AC$2:$AC$801,1)) -> 0.36071406 | D8: =SUMIFS(보유분석!$AM$2:$AM$801,보유분석!$V$2:$V$801,$A8,보유분석!$AC$2:$AC$801,1) -> 110319.63 | E8: =IF(SUMIFS(보유분석!$AM$2:$AM$801,보유분석!$AC$2:$AC$801,1)=0,0,D8/SUMIFS(보유분석!$AM$2:$AM$801,보유분석!$AC$2:$AC$801,1)) -> 0.29090952 | F8: =IF(SUMIFS(보유분석!$BB$2:$BB$801,보유분석!$V$2:$V$801,$A8,보유분석!$AC$2:$AC$801,1)=0,"",SUMIFS(보유분석!$BA$2:$BA$801,보유분석!$V$2:$V$801,$A8,보유분석!$AC$2:$AC$801,1)/SUMIFS(보유분석!$BB$2:$BB$801,보유분석!$V$2:$V$801,$A8,보유분석!$AC$2:$AC$801,1)) -> 5.5984355 | G8: =IF(F8="","",(F8-(SUMIFS(보유분석!$BA$2:$BA$801,보유분석!$AC$2:$AC$801,1)/SUMIFS(보유분석!$BB$2:$BB$801,보유분석!$AC$2:$AC$801,1)))*100) -> -6.1600335 | H8: =IF(SUMIFS(보유분석!$BD$2:$BD$801,보유분석!$V$2:$V$801,$A8,보유분석!$AC$2:$AC$801,1)=0,"",SUMIFS(보유분석!$BC$2:$BC$801,보유분석!$V$2:$V$801,$A8,보유분석!$AC$2:$AC$801,1)/SUMIFS(보유분석!$BD$2:$BD$801,보유분석!$V$2:$V$801,$A8,보유분석!$AC$2:$AC$801,1)) -> 64.795005 | I8: =IF(SUMIFS(보유분석!$BF$2:$BF$801,보유분석!$V$2:$V$801,$A8,보유분석!$AC$2:$AC$801,1)=0,"",SUMIFS(보유분석!$BE$2:$BE$801,보유분석!$V$2:$V$801,$A8,보유분석!$AC$2:$AC$801,1)/SUMIFS(보유분석!$BF$2:$BF$801,보유분석!$V$2:$V$801,$A8,보유분석!$AC$2:$AC$801,1)) -> 2.1699808 | J8: =IF(SUMIFS(보유분석!$BG$2:$BG$801,보유분석!$V$2:$V$801,$A8,보유분석!$AC$2:$AC$801,1)=0,"",(SUMIFS(보유분석!$BC$2:$BC$801,보유분석!$V$2:$V$801,$A8,보유분석!$AC$2:$AC$801,1)+SUMIFS(보유분석!$BH$2:$BH$801,보유분석!$V$2:$V$801,$A8,보유분석!$AC$2:$AC$801,1))/SUMIFS(보유분석!$BG$2:$BG$801,보유분석!$V$2:$V$801,$A8,보유분석!$AC$2:$AC$801,1)) -> 37.365885 | K8: =IF(B8=0,"",SUMIFS(보유분석!$AV$2:$AV$801,보유분석!$V$2:$V$801,$A8,보유분석!$AC$2:$AC$801,1)/(B8*1000000)) -> 0.057604986 | L8: =SUMIFS(보유분석!$AP$2:$AP$801,보유분석!$V$2:$V$801,$A8,보유분석!$AC$2:$AC$801,1) -> -13660126 | M8: =COUNTIFS(보유분석!$V$2:$V$801,$A8,보유분석!$AR$2:$AR$801,"Cheap",보유분석!$AC$2:$AC$801,1) -> 6 | N8: =COUNTIFS(보유분석!$V$2:$V$801,$A8,보유분석!$AR$2:$AR$801,"Rich",보유분석!$AC$2:$AC$801,1) -> 0 | P8: =IF(O8="","",O8-C8) | Q8: =-SUMIFS(보유분석!$AZ$2:$AZ$801,보유분석!$V$2:$V$801,$A8,보유분석!$AC$2:$AC$801,1)*설정!$C$10 -> -2714804.5 | R8: =IF((-SUMIFS(보유분석!$AZ$2:$AZ$801,보유분석!$AC$2:$AC$801,1)*설정!$C$10)=0,0,Q8/(-SUMIFS(보유분석!$AZ$2:$AZ$801,보유분석!$AC$2:$AC$801,1)*설정!$C$10)) -> 0.26675815 | S8: =IF(SUMIFS(보유분석!$BG$2:$BG$801,보유분석!$V$2:$V$801,$A8,보유분석!$AC$2:$AC$801,1)=0,"",SUMIFS(보유분석!$BH$2:$BH$801,보유분석!$V$2:$V$801,$A8,보유분석!$AC$2:$AC$801,1)/SUMIFS(보유분석!$BG$2:$BG$801,보유분석!$V$2:$V$801,$A8,보유분석!$AC$2:$AC$801,1)) -> 7.4899897 | T8: =IF(SUMIFS(보유분석!$BI$2:$BI$801,보유분석!$V$2:$V$801,$A8,보유분석!$AC$2:$AC$801,1)=0,"",SUMIFS(보유분석!$BD$2:$BD$801,보유분석!$V$2:$V$801,$A8,보유분석!$AC$2:$AC$801,1)/SUMIFS(보유분석!$BI$2:$BI$801,보유분석!$V$2:$V$801,$A8,보유분석!$AC$2:$AC$801,1)) -> 0.99765972
A9: 3-4년 | B9: =SUMIFS(보유분석!$AA$2:$AA$801,보유분석!$V$2:$V$801,$A9,보유분석!$AC$2:$AC$801,1) -> 308.28857 | C9: =IF(SUMIFS(보유분석!$AA$2:$AA$801,보유분석!$AC$2:$AC$801,1)=0,0,B9/SUMIFS(보유분석!$AA$2:$AA$801,보유분석!$AC$2:$AC$801,1)) -> 0.21873766 | D9: =SUMIFS(보유분석!$AM$2:$AM$801,보유분석!$V$2:$V$801,$A9,보유분석!$AC$2:$AC$801,1) -> 86820.39 | E9: =IF(SUMIFS(보유분석!$AM$2:$AM$801,보유분석!$AC$2:$AC$801,1)=0,0,D9/SUMIFS(보유분석!$AM$2:$AM$801,보유분석!$AC$2:$AC$801,1)) -> 0.22894273 | F9: =IF(SUMIFS(보유분석!$BB$2:$BB$801,보유분석!$V$2:$V$801,$A9,보유분석!$AC$2:$AC$801,1)=0,"",SUMIFS(보유분석!$BA$2:$BA$801,보유분석!$V$2:$V$801,$A9,보유분석!$AC$2:$AC$801,1)/SUMIFS(보유분석!$BB$2:$BB$801,보유분석!$V$2:$V$801,$A9,보유분석!$AC$2:$AC$801,1)) -> 5.7308698 | G9: =IF(F9="","",(F9-(SUMIFS(보유분석!$BA$2:$BA$801,보유분석!$AC$2:$AC$801,1)/SUMIFS(보유분석!$BB$2:$BB$801,보유분석!$AC$2:$AC$801,1)))*100) -> 7.0833927 | H9: =IF(SUMIFS(보유분석!$BD$2:$BD$801,보유분석!$V$2:$V$801,$A9,보유분석!$AC$2:$AC$801,1)=0,"",SUMIFS(보유분석!$BC$2:$BC$801,보유분석!$V$2:$V$801,$A9,보유분석!$AC$2:$AC$801,1)/SUMIFS(보유분석!$BD$2:$BD$801,보유분석!$V$2:$V$801,$A9,보유분석!$AC$2:$AC$801,1)) -> 67.697295 | I9: =IF(SUMIFS(보유분석!$BF$2:$BF$801,보유분석!$V$2:$V$801,$A9,보유분석!$AC$2:$AC$801,1)=0,"",SUMIFS(보유분석!$BE$2:$BE$801,보유분석!$V$2:$V$801,$A9,보유분석!$AC$2:$AC$801,1)/SUMIFS(보유분석!$BF$2:$BF$801,보유분석!$V$2:$V$801,$A9,보유분석!$AC$2:$AC$801,1)) -> 2.8162053 | J9: =IF(SUMIFS(보유분석!$BG$2:$BG$801,보유분석!$V$2:$V$801,$A9,보유분석!$AC$2:$AC$801,1)=0,"",(SUMIFS(보유분석!$BC$2:$BC$801,보유분석!$V$2:$V$801,$A9,보유분석!$AC$2:$AC$801,1)+SUMIFS(보유분석!$BH$2:$BH$801,보유분석!$V$2:$V$801,$A9,보유분석!$AC$2:$AC$801,1))/SUMIFS(보유분석!$BG$2:$BG$801,보유분석!$V$2:$V$801,$A9,보유분석!$AC$2:$AC$801,1)) -> 31.999892 | K9: =IF(B9=0,"",SUMIFS(보유분석!$AV$2:$AV$801,보유분석!$V$2:$V$801,$A9,보유분석!$AC$2:$AC$801,1)/(B9*1000000)) -> 0.059550795 | L9: =SUMIFS(보유분석!$AP$2:$AP$801,보유분석!$V$2:$V$801,$A9,보유분석!$AC$2:$AC$801,1) -> -11690080 | M9: =COUNTIFS(보유분석!$V$2:$V$801,$A9,보유분석!$AR$2:$AR$801,"Cheap",보유분석!$AC$2:$AC$801,1) -> 4 | N9: =COUNTIFS(보유분석!$V$2:$V$801,$A9,보유분석!$AR$2:$AR$801,"Rich",보유분석!$AC$2:$AC$801,1) -> 3 | P9: =IF(O9="","",O9-C9) | Q9: =-SUMIFS(보유분석!$AZ$2:$AZ$801,보유분석!$V$2:$V$801,$A9,보유분석!$AC$2:$AC$801,1)*설정!$C$10 -> -2257499.5 | R9: =IF((-SUMIFS(보유분석!$AZ$2:$AZ$801,보유분석!$AC$2:$AC$801,1)*설정!$C$10)=0,0,Q9/(-SUMIFS(보유분석!$AZ$2:$AZ$801,보유분석!$AC$2:$AC$801,1)*설정!$C$10)) -> 0.22182312 | S9: =IF(SUMIFS(보유분석!$BG$2:$BG$801,보유분석!$V$2:$V$801,$A9,보유분석!$AC$2:$AC$801,1)=0,"",SUMIFS(보유분석!$BH$2:$BH$801,보유분석!$V$2:$V$801,$A9,보유분석!$AC$2:$AC$801,1)/SUMIFS(보유분석!$BG$2:$BG$801,보유분석!$V$2:$V$801,$A9,보유분석!$AC$2:$AC$801,1)) -> 7.9614118 | T9: =IF(SUMIFS(보유분석!$BI$2:$BI$801,보유분석!$V$2:$V$801,$A9,보유분석!$AC$2:$AC$801,1)=0,"",SUMIFS(보유분석!$BD$2:$BD$801,보유분석!$V$2:$V$801,$A9,보유분석!$AC$2:$AC$801,1)/SUMIFS(보유분석!$BI$2:$BI$801,보유분석!$V$2:$V$801,$A9,보유분석!$AC$2:$AC$801,1)) -> 1
A10: 4-5년 | B10: =SUMIFS(보유분석!$AA$2:$AA$801,보유분석!$V$2:$V$801,$A10,보유분석!$AC$2:$AC$801,1) -> 196.73257 | C10: =IF(SUMIFS(보유분석!$AA$2:$AA$801,보유분석!$AC$2:$AC$801,1)=0,0,B10/SUMIFS(보유분석!$AA$2:$AA$801,보유분석!$AC$2:$AC$801,1)) -> 0.13958618 | D10: =SUMIFS(보유분석!$AM$2:$AM$801,보유분석!$V$2:$V$801,$A10,보유분석!$AC$2:$AC$801,1) -> 72774.59 | E10: =IF(SUMIFS(보유분석!$AM$2:$AM$801,보유분석!$AC$2:$AC$801,1)=0,0,D10/SUMIFS(보유분석!$AM$2:$AM$801,보유분석!$AC$2:$AC$801,1)) -> 0.19190438 | F10: =IF(SUMIFS(보유분석!$BB$2:$BB$801,보유분석!$V$2:$V$801,$A10,보유분석!$AC$2:$AC$801,1)=0,"",SUMIFS(보유분석!$BA$2:$BA$801,보유분석!$V$2:$V$801,$A10,보유분석!$AC$2:$AC$801,1)/SUMIFS(보유분석!$BB$2:$BB$801,보유분석!$V$2:$V$801,$A10,보유분석!$AC$2:$AC$801,1)) -> 5.8300814 | G10: =IF(F10="","",(F10-(SUMIFS(보유분석!$BA$2:$BA$801,보유분석!$AC$2:$AC$801,1)/SUMIFS(보유분석!$BB$2:$BB$801,보유분석!$AC$2:$AC$801,1)))*100) -> 17.004559 | H10: =IF(SUMIFS(보유분석!$BD$2:$BD$801,보유분석!$V$2:$V$801,$A10,보유분석!$AC$2:$AC$801,1)=0,"",SUMIFS(보유분석!$BC$2:$BC$801,보유분석!$V$2:$V$801,$A10,보유분석!$AC$2:$AC$801,1)/SUMIFS(보유분석!$BD$2:$BD$801,보유분석!$V$2:$V$801,$A10,보유분석!$AC$2:$AC$801,1)) -> 80.657112 | I10: =IF(SUMIFS(보유분석!$BF$2:$BF$801,보유분석!$V$2:$V$801,$A10,보유분석!$AC$2:$AC$801,1)=0,"",SUMIFS(보유분석!$BE$2:$BE$801,보유분석!$V$2:$V$801,$A10,보유분석!$AC$2:$AC$801,1)/SUMIFS(보유분석!$BF$2:$BF$801,보유분석!$V$2:$V$801,$A10,보유분석!$AC$2:$AC$801,1)) -> 3.6991632 | J10: =IF(SUMIFS(보유분석!$BG$2:$BG$801,보유분석!$V$2:$V$801,$A10,보유분석!$AC$2:$AC$801,1)=0,"",(SUMIFS(보유분석!$BC$2:$BC$801,보유분석!$V$2:$V$801,$A10,보유분석!$AC$2:$AC$801,1)+SUMIFS(보유분석!$BH$2:$BH$801,보유분석!$V$2:$V$801,$A10,보유분석!$AC$2:$AC$801,1))/SUMIFS(보유분석!$BG$2:$BG$801,보유분석!$V$2:$V$801,$A10,보유분석!$AC$2:$AC$801,1)) -> 27.471664 | K10: =IF(B10=0,"",SUMIFS(보유분석!$AV$2:$AV$801,보유분석!$V$2:$V$801,$A10,보유분석!$AC$2:$AC$801,1)/(B10*1000000)) -> 0.06039732 | L10: =SUMIFS(보유분석!$AP$2:$AP$801,보유분석!$V$2:$V$801,$A10,보유분석!$AC$2:$AC$801,1) -> -6935143.9 | M10: =COUNTIFS(보유분석!$V$2:$V$801,$A10,보유분석!$AR$2:$AR$801,"Cheap",보유분석!$AC$2:$AC$801,1) -> 21 | N10: =COUNTIFS(보유분석!$V$2:$V$801,$A10,보유분석!$AR$2:$AR$801,"Rich",보유분석!$AC$2:$AC$801,1) -> 2 | P10: =IF(O10="","",O10-C10) | Q10: =-SUMIFS(보유분석!$AZ$2:$AZ$801,보유분석!$V$2:$V$801,$A10,보유분석!$AC$2:$AC$801,1)*설정!$C$10 -> -2232476 | R10: =IF((-SUMIFS(보유분석!$AZ$2:$AZ$801,보유분석!$AC$2:$AC$801,1)*설정!$C$10)=0,0,Q10/(-SUMIFS(보유분석!$AZ$2:$AZ$801,보유분석!$AC$2:$AC$801,1)*설정!$C$10)) -> 0.21936429 | S10: =IF(SUMIFS(보유분석!$BG$2:$BG$801,보유분석!$V$2:$V$801,$A10,보유분석!$AC$2:$AC$801,1)=0,"",SUMIFS(보유분석!$BH$2:$BH$801,보유분석!$V$2:$V$801,$A10,보유분석!$AC$2:$AC$801,1)/SUMIFS(보유분석!$BG$2:$BG$801,보유분석!$V$2:$V$801,$A10,보유분석!$AC$2:$AC$801,1)) -> 5.6675128 | T10: =IF(SUMIFS(보유분석!$BI$2:$BI$801,보유분석!$V$2:$V$801,$A10,보유분석!$AC$2:$AC$801,1)=0,"",SUMIFS(보유분석!$BD$2:$BD$801,보유분석!$V$2:$V$801,$A10,보유분석!$AC$2:$AC$801,1)/SUMIFS(보유분석!$BI$2:$BI$801,보유분석!$V$2:$V$801,$A10,보유분석!$AC$2:$AC$801,1)) -> 1
A11: 5-7년 | B11: =SUMIFS(보유분석!$AA$2:$AA$801,보유분석!$V$2:$V$801,$A11,보유분석!$AC$2:$AC$801,1) -> 132.09165 | C11: =IF(SUMIFS(보유분석!$AA$2:$AA$801,보유분석!$AC$2:$AC$801,1)=0,0,B11/SUMIFS(보유분석!$AA$2:$AA$801,보유분석!$AC$2:$AC$801,1)) -> 0.093721991 | D11: =SUMIFS(보유분석!$AM$2:$AM$801,보유분석!$V$2:$V$801,$A11,보유분석!$AC$2:$AC$801,1) -> 53625.85 | E11: =IF(SUMIFS(보유분석!$AM$2:$AM$801,보유분석!$AC$2:$AC$801,1)=0,0,D11/SUMIFS(보유분석!$AM$2:$AM$801,보유분석!$AC$2:$AC$801,1)) -> 0.14140974 | F11: =IF(SUMIFS(보유분석!$BB$2:$BB$801,보유분석!$V$2:$V$801,$A11,보유분석!$AC$2:$AC$801,1)=0,"",SUMIFS(보유분석!$BA$2:$BA$801,보유분석!$V$2:$V$801,$A11,보유분석!$AC$2:$AC$801,1)/SUMIFS(보유분석!$BB$2:$BB$801,보유분석!$V$2:$V$801,$A11,보유분석!$AC$2:$AC$801,1)) -> 5.8555383 | G11: =IF(F11="","",(F11-(SUMIFS(보유분석!$BA$2:$BA$801,보유분석!$AC$2:$AC$801,1)/SUMIFS(보유분석!$BB$2:$BB$801,보유분석!$AC$2:$AC$801,1)))*100) -> 19.550246 | H11: =IF(SUMIFS(보유분석!$BD$2:$BD$801,보유분석!$V$2:$V$801,$A11,보유분석!$AC$2:$AC$801,1)=0,"",SUMIFS(보유분석!$BC$2:$BC$801,보유분석!$V$2:$V$801,$A11,보유분석!$AC$2:$AC$801,1)/SUMIFS(보유분석!$BD$2:$BD$801,보유분석!$V$2:$V$801,$A11,보유분석!$AC$2:$AC$801,1)) -> 83.815774 | I11: =IF(SUMIFS(보유분석!$BF$2:$BF$801,보유분석!$V$2:$V$801,$A11,보유분석!$AC$2:$AC$801,1)=0,"",SUMIFS(보유분석!$BE$2:$BE$801,보유분석!$V$2:$V$801,$A11,보유분석!$AC$2:$AC$801,1)/SUMIFS(보유분석!$BF$2:$BF$801,보유분석!$V$2:$V$801,$A11,보유분석!$AC$2:$AC$801,1)) -> 4.0597457 | J11: =IF(SUMIFS(보유분석!$BG$2:$BG$801,보유분석!$V$2:$V$801,$A11,보유분석!$AC$2:$AC$801,1)=0,"",(SUMIFS(보유분석!$BC$2:$BC$801,보유분석!$V$2:$V$801,$A11,보유분석!$AC$2:$AC$801,1)+SUMIFS(보유분석!$BH$2:$BH$801,보유분석!$V$2:$V$801,$A11,보유분석!$AC$2:$AC$801,1))/SUMIFS(보유분석!$BG$2:$BG$801,보유분석!$V$2:$V$801,$A11,보유분석!$AC$2:$AC$801,1)) -> 25.763764 | K11: =IF(B11=0,"",SUMIFS(보유분석!$AV$2:$AV$801,보유분석!$V$2:$V$801,$A11,보유분석!$AC$2:$AC$801,1)/(B11*1000000)) -> 0.060361974 | L11: =SUMIFS(보유분석!$AP$2:$AP$801,보유분석!$V$2:$V$801,$A11,보유분석!$AC$2:$AC$801,1) -> -5502163.8 | M11: =COUNTIFS(보유분석!$V$2:$V$801,$A11,보유분석!$AR$2:$AR$801,"Cheap",보유분석!$AC$2:$AC$801,1) -> 3 | N11: =COUNTIFS(보유분석!$V$2:$V$801,$A11,보유분석!$AR$2:$AR$801,"Rich",보유분석!$AC$2:$AC$801,1) -> 3 | P11: =IF(O11="","",O11-C11) | Q11: =-SUMIFS(보유분석!$AZ$2:$AZ$801,보유분석!$V$2:$V$801,$A11,보유분석!$AC$2:$AC$801,1)*설정!$C$10 -> -1636355.4 | R11: =IF((-SUMIFS(보유분석!$AZ$2:$AZ$801,보유분석!$AC$2:$AC$801,1)*설정!$C$10)=0,0,Q11/(-SUMIFS(보유분석!$AZ$2:$AZ$801,보유분석!$AC$2:$AC$801,1)*설정!$C$10)) -> 0.16078916 | S11: =IF(SUMIFS(보유분석!$BG$2:$BG$801,보유분석!$V$2:$V$801,$A11,보유분석!$AC$2:$AC$801,1)=0,"",SUMIFS(보유분석!$BH$2:$BH$801,보유분석!$V$2:$V$801,$A11,보유분석!$AC$2:$AC$801,1)/SUMIFS(보유분석!$BG$2:$BG$801,보유분석!$V$2:$V$801,$A11,보유분석!$AC$2:$AC$801,1)) -> 5.197739 | T11: =IF(SUMIFS(보유분석!$BI$2:$BI$801,보유분석!$V$2:$V$801,$A11,보유분석!$AC$2:$AC$801,1)=0,"",SUMIFS(보유분석!$BD$2:$BD$801,보유분석!$V$2:$V$801,$A11,보유분석!$AC$2:$AC$801,1)/SUMIFS(보유분석!$BI$2:$BI$801,보유분석!$V$2:$V$801,$A11,보유분석!$AC$2:$AC$801,1)) -> 0.85284497
A12: 7-10년 | B12: =SUMIFS(보유분석!$AA$2:$AA$801,보유분석!$V$2:$V$801,$A12,보유분석!$AC$2:$AC$801,1) -> 38.766482 | C12: =IF(SUMIFS(보유분석!$AA$2:$AA$801,보유분석!$AC$2:$AC$801,1)=0,0,B12/SUMIFS(보유분석!$AA$2:$AA$801,보유분석!$AC$2:$AC$801,1)) -> 0.02750569 | D12: =SUMIFS(보유분석!$AM$2:$AM$801,보유분석!$V$2:$V$801,$A12,보유분석!$AC$2:$AC$801,1) -> 26299.939 | E12: =IF(SUMIFS(보유분석!$AM$2:$AM$801,보유분석!$AC$2:$AC$801,1)=0,0,D12/SUMIFS(보유분석!$AM$2:$AM$801,보유분석!$AC$2:$AC$801,1)) -> 0.069352141 | F12: =IF(SUMIFS(보유분석!$BB$2:$BB$801,보유분석!$V$2:$V$801,$A12,보유분석!$AC$2:$AC$801,1)=0,"",SUMIFS(보유분석!$BA$2:$BA$801,보유분석!$V$2:$V$801,$A12,보유분석!$AC$2:$AC$801,1)/SUMIFS(보유분석!$BB$2:$BB$801,보유분석!$V$2:$V$801,$A12,보유분석!$AC$2:$AC$801,1)) -> 5.8601636 | G12: =IF(F12="","",(F12-(SUMIFS(보유분석!$BA$2:$BA$801,보유분석!$AC$2:$AC$801,1)/SUMIFS(보유분석!$BB$2:$BB$801,보유분석!$AC$2:$AC$801,1)))*100) -> 20.012779 | H12: =IF(SUMIFS(보유분석!$BD$2:$BD$801,보유분석!$V$2:$V$801,$A12,보유분석!$AC$2:$AC$801,1)=0,"",SUMIFS(보유분석!$BC$2:$BC$801,보유분석!$V$2:$V$801,$A12,보유분석!$AC$2:$AC$801,1)/SUMIFS(보유분석!$BD$2:$BD$801,보유분석!$V$2:$V$801,$A12,보유분석!$AC$2:$AC$801,1)) -> 110.38725 | I12: =IF(SUMIFS(보유분석!$BF$2:$BF$801,보유분석!$V$2:$V$801,$A12,보유분석!$AC$2:$AC$801,1)=0,"",SUMIFS(보유분석!$BE$2:$BE$801,보유분석!$V$2:$V$801,$A12,보유분석!$AC$2:$AC$801,1)/SUMIFS(보유분석!$BF$2:$BF$801,보유분석!$V$2:$V$801,$A12,보유분석!$AC$2:$AC$801,1)) -> 6.7841955 | J12: =IF(SUMIFS(보유분석!$BG$2:$BG$801,보유분석!$V$2:$V$801,$A12,보유분석!$AC$2:$AC$801,1)=0,"",(SUMIFS(보유분석!$BC$2:$BC$801,보유분석!$V$2:$V$801,$A12,보유분석!$AC$2:$AC$801,1)+SUMIFS(보유분석!$BH$2:$BH$801,보유분석!$V$2:$V$801,$A12,보유분석!$AC$2:$AC$801,1))/SUMIFS(보유분석!$BG$2:$BG$801,보유분석!$V$2:$V$801,$A12,보유분석!$AC$2:$AC$801,1)) -> 20.501076 | K12: =IF(B12=0,"",SUMIFS(보유분석!$AV$2:$AV$801,보유분석!$V$2:$V$801,$A12,보유분석!$AC$2:$AC$801,1)/(B12*1000000)) -> 0.06026933 | L12: =SUMIFS(보유분석!$AP$2:$AP$801,보유분석!$V$2:$V$801,$A12,보유분석!$AC$2:$AC$801,1) -> -2741936.7 | M12: =COUNTIFS(보유분석!$V$2:$V$801,$A12,보유분석!$AR$2:$AR$801,"Cheap",보유분석!$AC$2:$AC$801,1) -> 1 | N12: =COUNTIFS(보유분석!$V$2:$V$801,$A12,보유분석!$AR$2:$AR$801,"Rich",보유분석!$AC$2:$AC$801,1) -> 1 | P12: =IF(O12="","",O12-C12) | Q12: =-SUMIFS(보유분석!$AZ$2:$AZ$801,보유분석!$V$2:$V$801,$A12,보유분석!$AC$2:$AC$801,1)*설정!$C$10 -> -641823.15 | R12: =IF((-SUMIFS(보유분석!$AZ$2:$AZ$801,보유분석!$AC$2:$AC$801,1)*설정!$C$10)=0,0,Q12/(-SUMIFS(보유분석!$AZ$2:$AZ$801,보유분석!$AC$2:$AC$801,1)*설정!$C$10)) -> 0.063065889 | S12: =IF(SUMIFS(보유분석!$BG$2:$BG$801,보유분석!$V$2:$V$801,$A12,보유분석!$AC$2:$AC$801,1)=0,"",SUMIFS(보유분석!$BH$2:$BH$801,보유분석!$V$2:$V$801,$A12,보유분석!$AC$2:$AC$801,1)/SUMIFS(보유분석!$BG$2:$BG$801,보유분석!$V$2:$V$801,$A12,보유분석!$AC$2:$AC$801,1)) -> 4.1833274 | T12: =IF(SUMIFS(보유분석!$BI$2:$BI$801,보유분석!$V$2:$V$801,$A12,보유분석!$AC$2:$AC$801,1)=0,"",SUMIFS(보유분석!$BD$2:$BD$801,보유분석!$V$2:$V$801,$A12,보유분석!$AC$2:$AC$801,1)/SUMIFS(보유분석!$BI$2:$BI$801,보유분석!$V$2:$V$801,$A12,보유분석!$AC$2:$AC$801,1)) -> 1
A13: 10-20년 | B13: =SUMIFS(보유분석!$AA$2:$AA$801,보유분석!$V$2:$V$801,$A13,보유분석!$AC$2:$AC$801,1) -> 2.740295 | C13: =IF(SUMIFS(보유분석!$AA$2:$AA$801,보유분석!$AC$2:$AC$801,1)=0,0,B13/SUMIFS(보유분석!$AA$2:$AA$801,보유분석!$AC$2:$AC$801,1)) -> 0.0019443009 | D13: =SUMIFS(보유분석!$AM$2:$AM$801,보유분석!$V$2:$V$801,$A13,보유분석!$AC$2:$AC$801,1) -> 1919.604 | E13: =IF(SUMIFS(보유분석!$AM$2:$AM$801,보유분석!$AC$2:$AC$801,1)=0,0,D13/SUMIFS(보유분석!$AM$2:$AM$801,보유분석!$AC$2:$AC$801,1)) -> 0.0050619375 | F13: =IF(SUMIFS(보유분석!$BB$2:$BB$801,보유분석!$V$2:$V$801,$A13,보유분석!$AC$2:$AC$801,1)=0,"",SUMIFS(보유분석!$BA$2:$BA$801,보유분석!$V$2:$V$801,$A13,보유분석!$AC$2:$AC$801,1)/SUMIFS(보유분석!$BB$2:$BB$801,보유분석!$V$2:$V$801,$A13,보유분석!$AC$2:$AC$801,1)) -> 6.054946 | G13: =IF(F13="","",(F13-(SUMIFS(보유분석!$BA$2:$BA$801,보유분석!$AC$2:$AC$801,1)/SUMIFS(보유분석!$BB$2:$BB$801,보유분석!$AC$2:$AC$801,1)))*100) -> 39.49102 | H13: =IF(SUMIFS(보유분석!$BD$2:$BD$801,보유분석!$V$2:$V$801,$A13,보유분석!$AC$2:$AC$801,1)=0,"",SUMIFS(보유분석!$BC$2:$BC$801,보유분석!$V$2:$V$801,$A13,보유분석!$AC$2:$AC$801,1)/SUMIFS(보유분석!$BD$2:$BD$801,보유분석!$V$2:$V$801,$A13,보유분석!$AC$2:$AC$801,1)) -> 84.825675 | I13: =IF(SUMIFS(보유분석!$BF$2:$BF$801,보유분석!$V$2:$V$801,$A13,보유분석!$AC$2:$AC$801,1)=0,"",SUMIFS(보유분석!$BE$2:$BE$801,보유분석!$V$2:$V$801,$A13,보유분석!$AC$2:$AC$801,1)/SUMIFS(보유분석!$BF$2:$BF$801,보유분석!$V$2:$V$801,$A13,보유분석!$AC$2:$AC$801,1)) -> 7.0050998 | J13: =IF(SUMIFS(보유분석!$BG$2:$BG$801,보유분석!$V$2:$V$801,$A13,보유분석!$AC$2:$AC$801,1)=0,"",(SUMIFS(보유분석!$BC$2:$BC$801,보유분석!$V$2:$V$801,$A13,보유분석!$AC$2:$AC$801,1)+SUMIFS(보유분석!$BH$2:$BH$801,보유분석!$V$2:$V$801,$A13,보유분석!$AC$2:$AC$801,1))/SUMIFS(보유분석!$BG$2:$BG$801,보유분석!$V$2:$V$801,$A13,보유분석!$AC$2:$AC$801,1)) -> 14.743562 | K13: =IF(B13=0,"",SUMIFS(보유분석!$AV$2:$AV$801,보유분석!$V$2:$V$801,$A13,보유분석!$AC$2:$AC$801,1)/(B13*1000000)) -> 0.062394905 | L13: =SUMIFS(보유분석!$AP$2:$AP$801,보유분석!$V$2:$V$801,$A13,보유분석!$AC$2:$AC$801,1) -> -244509 | M13: =COUNTIFS(보유분석!$V$2:$V$801,$A13,보유분석!$AR$2:$AR$801,"Cheap",보유분석!$AC$2:$AC$801,1) -> 0 | N13: =COUNTIFS(보유분석!$V$2:$V$801,$A13,보유분석!$AR$2:$AR$801,"Rich",보유분석!$AC$2:$AC$801,1) -> 0 | P13: =IF(O13="","",O13-C13) | Q13: =-SUMIFS(보유분석!$AZ$2:$AZ$801,보유분석!$V$2:$V$801,$A13,보유분석!$AC$2:$AC$801,1)*설정!$C$10 -> -61589.087 | R13: =IF((-SUMIFS(보유분석!$AZ$2:$AZ$801,보유분석!$AC$2:$AC$801,1)*설정!$C$10)=0,0,Q13/(-SUMIFS(보유분석!$AZ$2:$AZ$801,보유분석!$AC$2:$AC$801,1)*설정!$C$10)) -> 0.0060517769 | S13: =IF(SUMIFS(보유분석!$BG$2:$BG$801,보유분석!$V$2:$V$801,$A13,보유분석!$AC$2:$AC$801,1)=0,"",SUMIFS(보유분석!$BH$2:$BH$801,보유분석!$V$2:$V$801,$A13,보유분석!$AC$2:$AC$801,1)/SUMIFS(보유분석!$BG$2:$BG$801,보유분석!$V$2:$V$801,$A13,보유분석!$AC$2:$AC$801,1)) -> 2.6344303 | T13: =IF(SUMIFS(보유분석!$BI$2:$BI$801,보유분석!$V$2:$V$801,$A13,보유분석!$AC$2:$AC$801,1)=0,"",SUMIFS(보유분석!$BD$2:$BD$801,보유분석!$V$2:$V$801,$A13,보유분석!$AC$2:$AC$801,1)/SUMIFS(보유분석!$BI$2:$BI$801,보유분석!$V$2:$V$801,$A13,보유분석!$AC$2:$AC$801,1)) -> 1
A14: 20년 이상 | B14: =SUMIFS(보유분석!$AA$2:$AA$801,보유분석!$V$2:$V$801,$A14,보유분석!$AC$2:$AC$801,1) -> 3.6444222 | C14: =IF(SUMIFS(보유분석!$AA$2:$AA$801,보유분석!$AC$2:$AC$801,1)=0,0,B14/SUMIFS(보유분석!$AA$2:$AA$801,보유분석!$AC$2:$AC$801,1)) -> 0.0025857994 | D14: =SUMIFS(보유분석!$AM$2:$AM$801,보유분석!$V$2:$V$801,$A14,보유분석!$AC$2:$AC$801,1) -> 5409.5617 | E14: =IF(SUMIFS(보유분석!$AM$2:$AM$801,보유분석!$AC$2:$AC$801,1)=0,0,D14/SUMIFS(보유분석!$AM$2:$AM$801,보유분석!$AC$2:$AC$801,1)) -> 0.01426485 | F14: =IF(SUMIFS(보유분석!$BB$2:$BB$801,보유분석!$V$2:$V$801,$A14,보유분석!$AC$2:$AC$801,1)=0,"",SUMIFS(보유분석!$BA$2:$BA$801,보유분석!$V$2:$V$801,$A14,보유분석!$AC$2:$AC$801,1)/SUMIFS(보유분석!$BB$2:$BB$801,보유분석!$V$2:$V$801,$A14,보유분석!$AC$2:$AC$801,1)) -> 6.1861 | G14: =IF(F14="","",(F14-(SUMIFS(보유분석!$BA$2:$BA$801,보유분석!$AC$2:$AC$801,1)/SUMIFS(보유분석!$BB$2:$BB$801,보유분석!$AC$2:$AC$801,1)))*100) -> 52.606418 | H14: =IF(SUMIFS(보유분석!$BD$2:$BD$801,보유분석!$V$2:$V$801,$A14,보유분석!$AC$2:$AC$801,1)=0,"",SUMIFS(보유분석!$BC$2:$BC$801,보유분석!$V$2:$V$801,$A14,보유분석!$AC$2:$AC$801,1)/SUMIFS(보유분석!$BD$2:$BD$801,보유분석!$V$2:$V$801,$A14,보유분석!$AC$2:$AC$801,1)) -> 64.761 | I14: =IF(SUMIFS(보유분석!$BF$2:$BF$801,보유분석!$V$2:$V$801,$A14,보유분석!$AC$2:$AC$801,1)=0,"",SUMIFS(보유분석!$BE$2:$BE$801,보유분석!$V$2:$V$801,$A14,보유분석!$AC$2:$AC$801,1)/SUMIFS(보유분석!$BF$2:$BF$801,보유분석!$V$2:$V$801,$A14,보유분석!$AC$2:$AC$801,1)) -> 14.8434 | J14: =IF(SUMIFS(보유분석!$BG$2:$BG$801,보유분석!$V$2:$V$801,$A14,보유분석!$AC$2:$AC$801,1)=0,"",(SUMIFS(보유분석!$BC$2:$BC$801,보유분석!$V$2:$V$801,$A14,보유분석!$AC$2:$AC$801,1)+SUMIFS(보유분석!$BH$2:$BH$801,보유분석!$V$2:$V$801,$A14,보유분석!$AC$2:$AC$801,1))/SUMIFS(보유분석!$BG$2:$BG$801,보유분석!$V$2:$V$801,$A14,보유분석!$AC$2:$AC$801,1)) -> 5.5551675 | K14: =IF(B14=0,"",SUMIFS(보유분석!$AV$2:$AV$801,보유분석!$V$2:$V$801,$A14,보유분석!$AC$2:$AC$801,1)/(B14*1000000)) -> 0.063630657 | L14: =SUMIFS(보유분석!$AP$2:$AP$801,보유분석!$V$2:$V$801,$A14,보유분석!$AC$2:$AC$801,1) -> -496779.68 | M14: =COUNTIFS(보유분석!$V$2:$V$801,$A14,보유분석!$AR$2:$AR$801,"Cheap",보유분석!$AC$2:$AC$801,1) -> 0 | N14: =COUNTIFS(보유분석!$V$2:$V$801,$A14,보유분석!$AR$2:$AR$801,"Rich",보유분석!$AC$2:$AC$801,1) -> 0 | P14: =IF(O14="","",O14-C14) | Q14: =-SUMIFS(보유분석!$AZ$2:$AZ$801,보유분석!$V$2:$V$801,$A14,보유분석!$AC$2:$AC$801,1)*설정!$C$10 -> -132471.41 | R14: =IF((-SUMIFS(보유분석!$AZ$2:$AZ$801,보유분석!$AC$2:$AC$801,1)*설정!$C$10)=0,0,Q14/(-SUMIFS(보유분석!$AZ$2:$AZ$801,보유분석!$AC$2:$AC$801,1)*설정!$C$10)) -> 0.013016712 | S14: =IF(SUMIFS(보유분석!$BG$2:$BG$801,보유분석!$V$2:$V$801,$A14,보유분석!$AC$2:$AC$801,1)=0,"",SUMIFS(보유분석!$BH$2:$BH$801,보유분석!$V$2:$V$801,$A14,보유분석!$AC$2:$AC$801,1)/SUMIFS(보유분석!$BG$2:$BG$801,보유분석!$V$2:$V$801,$A14,보유분석!$AC$2:$AC$801,1)) -> 1.1922183 | T14: =IF(SUMIFS(보유분석!$BI$2:$BI$801,보유분석!$V$2:$V$801,$A14,보유분석!$AC$2:$AC$801,1)=0,"",SUMIFS(보유분석!$BD$2:$BD$801,보유분석!$V$2:$V$801,$A14,보유분석!$AC$2:$AC$801,1)/SUMIFS(보유분석!$BI$2:$BI$801,보유분석!$V$2:$V$801,$A14,보유분석!$AC$2:$AC$801,1)) -> 1
A15: 기타(목록외) | B15: =SUMPRODUCT(ISNA(MATCH(보유분석!$V$2:$V$801,$A$6:$A$14,0))*(보유분석!$AC$2:$AC$801=1)*보유분석!$AA$2:$AA$801) -> 0 | C15: =IF(SUMIFS(보유분석!$AA$2:$AA$801,보유분석!$AC$2:$AC$801,1)=0,0,B15/SUMIFS(보유분석!$AA$2:$AA$801,보유분석!$AC$2:$AC$801,1)) -> 0 | D15: =SUMPRODUCT(ISNA(MATCH(보유분석!$V$2:$V$801,$A$6:$A$14,0))*(보유분석!$AC$2:$AC$801=1)*보유분석!$AM$2:$AM$801) -> 0 | E15: =IF(SUMIFS(보유분석!$AM$2:$AM$801,보유분석!$AC$2:$AC$801,1)=0,0,D15/SUMIFS(보유분석!$AM$2:$AM$801,보유분석!$AC$2:$AC$801,1)) -> 0 | F15: =IF(SUMPRODUCT(ISNA(MATCH(보유분석!$V$2:$V$801,$A$6:$A$14,0))*(보유분석!$AC$2:$AC$801=1)*보유분석!$BB$2:$BB$801)=0,"",SUMPRODUCT(ISNA(MATCH(보유분석!$V$2:$V$801,$A$6:$A$14,0))*(보유분석!$AC$2:$AC$801=1)*보유분석!$BA$2:$BA$801)/SUMPRODUCT(ISNA(MATCH(보유분석!$V$2:$V$801,$A$6:$A$14,0))*(보유분석!$AC$2:$AC$801=1)*보유분석!$BB$2:$BB$801)) | G15: =IF(F15="","",(F15-(SUMIFS(보유분석!$BA$2:$BA$801,보유분석!$AC$2:$AC$801,1)/SUMIFS(보유분석!$BB$2:$BB$801,보유분석!$AC$2:$AC$801,1)))*100) | H15: =IF(SUMPRODUCT(ISNA(MATCH(보유분석!$V$2:$V$801,$A$6:$A$14,0))*(보유분석!$AC$2:$AC$801=1)*보유분석!$BD$2:$BD$801)=0,"",SUMPRODUCT(ISNA(MATCH(보유분석!$V$2:$V$801,$A$6:$A$14,0))*(보유분석!$AC$2:$AC$801=1)*보유분석!$BC$2:$BC$801)/SUMPRODUCT(ISNA(MATCH(보유분석!$V$2:$V$801,$A$6:$A$14,0))*(보유분석!$AC$2:$AC$801=1)*보유분석!$BD$2:$BD$801)) | I15: =IF(SUMPRODUCT(ISNA(MATCH(보유분석!$V$2:$V$801,$A$6:$A$14,0))*(보유분석!$AC$2:$AC$801=1)*보유분석!$BF$2:$BF$801)=0,"",SUMPRODUCT(ISNA(MATCH(보유분석!$V$2:$V$801,$A$6:$A$14,0))*(보유분석!$AC$2:$AC$801=1)*보유분석!$BE$2:$BE$801)/SUMPRODUCT(ISNA(MATCH(보유분석!$V$2:$V$801,$A$6:$A$14,0))*(보유분석!$AC$2:$AC$801=1)*보유분석!$BF$2:$BF$801)) | J15: =IF(SUMPRODUCT(ISNA(MATCH(보유분석!$V$2:$V$801,$A$6:$A$14,0))*(보유분석!$AC$2:$AC$801=1)*보유분석!$BG$2:$BG$801)=0,"",(SUMPRODUCT(ISNA(MATCH(보유분석!$V$2:$V$801,$A$6:$A$14,0))*(보유분석!$AC$2:$AC$801=1)*보유분석!$BC$2:$BC$801)+SUMPRODUCT(ISNA(MATCH(보유분석!$V$2:$V$801,$A$6:$A$14,0))*(보유분석!$AC$2:$AC$801=1)*보유분석!$BH$2:$BH$801))/SUMPRODUCT(ISNA(MATCH(보유분석!$V$2:$V$801,$A$6:$A$14,0))*(보유분석!$AC$2:$AC$801=1)*보유분석!$BG$2:$BG$801)) | K15: =IF(B15=0,"",SUMPRODUCT(ISNA(MATCH(보유분석!$V$2:$V$801,$A$6:$A$14,0))*(보유분석!$AC$2:$AC$801=1)*보유분석!$AV$2:$AV$801)/(B15*1000000)) | L15: =SUMPRODUCT(ISNA(MATCH(보유분석!$V$2:$V$801,$A$6:$A$14,0))*(보유분석!$AC$2:$AC$801=1)*보유분석!$AP$2:$AP$801) -> 0 | M15: =SUMPRODUCT(ISNA(MATCH(보유분석!$V$2:$V$801,$A$6:$A$14,0))*(보유분석!$AC$2:$AC$801=1)*(보유분석!$AR$2:$AR$801="Cheap")) -> 0 | N15: =SUMPRODUCT(ISNA(MATCH(보유분석!$V$2:$V$801,$A$6:$A$14,0))*(보유분석!$AC$2:$AC$801=1)*(보유분석!$AR$2:$AR$801="Rich")) -> 0 | P15: =IF(O15="","",O15-C15) | Q15: =-SUMPRODUCT(ISNA(MATCH(보유분석!$V$2:$V$801,$A$6:$A$14,0))*(보유분석!$AC$2:$AC$801=1)*보유분석!$AZ$2:$AZ$801)*설정!$C$10 -> 0 | R15: =IF((-SUMIFS(보유분석!$AZ$2:$AZ$801,보유분석!$AC$2:$AC$801,1)*설정!$C$10)=0,0,Q15/(-SUMIFS(보유분석!$AZ$2:$AZ$801,보유분석!$AC$2:$AC$801,1)*설정!$C$10)) -> 0 | S15: =IF(SUMPRODUCT(ISNA(MATCH(보유분석!$V$2:$V$801,$A$6:$A$14,0))*(보유분석!$AC$2:$AC$801=1)*보유분석!$BG$2:$BG$801)=0,"",SUMPRODUCT(ISNA(MATCH(보유분석!$V$2:$V$801,$A$6:$A$14,0))*(보유분석!$AC$2:$AC$801=1)*보유분석!$BH$2:$BH$801)/SUMPRODUCT(ISNA(MATCH(보유분석!$V$2:$V$801,$A$6:$A$14,0))*(보유분석!$AC$2:$AC$801=1)*보유분석!$BG$2:$BG$801)) | T15: =IF(SUMPRODUCT(ISNA(MATCH(보유분석!$V$2:$V$801,$A$6:$A$14,0))*(보유분석!$AC$2:$AC$801=1)*보유분석!$BI$2:$BI$801)=0,"",SUMPRODUCT(ISNA(MATCH(보유분석!$V$2:$V$801,$A$6:$A$14,0))*(보유분석!$AC$2:$AC$801=1)*보유분석!$BD$2:$BD$801)/SUMPRODUCT(ISNA(MATCH(보유분석!$V$2:$V$801,$A$6:$A$14,0))*(보유분석!$AC$2:$AC$801=1)*보유분석!$BI$2:$BI$801))
